Workbook

Sheet Total
F1: 2025 PI | N1: 2025 Micro | Z1: 2025 CIB | AL1: 2025 Business Micro+Cib | AX1: 2026 | AY1: PI | BI1: Micro | BU1: CIB | CG1: Business CIB + Micro
A2: Branch | B2: Branch/City | C2: Popullsia | D2: Pop >15 | E2: NO Business | F2: Active Clients PI | G2: CA | H2: SA | I2: TDA | J2: Mortgage Loans | K2: Consumer Loans | L2: CC | M2: OVD | N2: Count of id | O2: Sum of CA | P2: Sum of SAV | Q2: Sum of TDA | R2: Sum of Short_term | S2: Sum of Long_term | T2: Sum of credit_card_pca | U2: Sum of Overdraft | V2: Sum of debit_card | W2: Sum of M_Banking | X2: Sum of E_Banking | Y2: Sum of POS | Z2: Count of id | AA2: Sum of CA | AB2: Sum of SAV | AC2: Sum of TDA | AD2: Sum of Short_term | AE2: Sum of Long_term | AF2: Sum of credit_card_pca | AG2: Sum of Overdraft | AH2: Sum of debit_card | AI2: Sum of M_Banking | AJ2: Sum of E_Banking | AK2: Sum of POS | AL2: Count of id | AM2: Sum of CA | AN2: SA | AO2: TDA | AP2: Short_term | AQ2: Long_term | AR2: credit_card | AS2: Overdraft | AT2: debit_card | AU2: M_Banking | AV2: E_Banking | AW2: POS | AX2: PI Active Clients | AY2: CA | AZ2: SA | BA2: TDA | BB2: Mortgage Loans | BC2: Consumer Loans | BD2: CC | BE2: OVD | BF2: Debit Cards | BG2: M Banking | BH2: E Banking | BI2: Active Clients | BJ2: CA | BK2: SA | BL2: TDA | BM2: Short Term Loans | BN2: Long Term Loans | BO2: CC | BP2: Debit Cards | BQ2: OVD | BR2: M Banking | BS2: E Banking | BT2: POS | BU2: Active Clients | BV2: CA | BW2: SA | BX2: TDA | BY2: Short Term Loans | BZ2: Long Term Loans | CA2: CC | CB2: Debit Cards | CC2: OVD | CD2: M Banking | CE2: E Banking | CF2: POS | CG2: Active Clients | CH2: CA | CI2: SA | CJ2: TDA | CK2: Short Term Loans | CL2: Long Term Loans | CM2: CC | CN2: Debit Cards | CO2: OVD | CP2: M Banking | CQ2: E Banking | CR2: POS
A3: 0001 | B3: PRISHTINË | C3: 227466 | D3: 177302 | E3: 21396 | F3: 45420 | G3: 48925 | H3: 4854 | I3: 4391 | J3: 3305 | K3: 6327 | L3: 7209 | M3: 3597 | N3: 3524 | O3: 3825 | P3: 0 | Q3: 7 | R3: 38 | S3: 554 | T3: 117 | U3: 119 | V3: 0 | Y3: 540 | Z3: 644 | AA3: 85 | AB3: 0 | AC3: 63 | AD3: 16 | AE3: 25 | AF3: 11 | AG3: 15 | AH3: 0 | AI3: 0 | AJ3: 0 | AK3: 148 | AL3: =Z3+N3 -> 4168 | AM3: =AA3+O3 -> 3910 | AN3: =AB3+P3 -> 0 | AO3: =AC3+Q3 -> 70 | AP3: =AD3+R3 -> 54 | AQ3: =AE3+S3 -> 579 | AR3: =AF3+T3 -> 128 | AS3: =AG3+U3 -> 134 | ... AW3: =AK3+Y3 -> 688 | AX3: 47635 | AY3: 52720 | AZ3: 9546 | BA3: 2444 | BB3: 3386 | BC3: 7665 | BD3: 7458 | BE3: 3781 | BF3: 53048 | BG3: 29710 | BH3: 5370 | BI3: 3560 | BJ3: 4081 | BK3: 1 | BL3: 14 | BM3: 32 | BN3: 507 | BO3: 124 | BP3: 3835 | BQ3: 122 | BR3: 2938 | BS3: 2381 | BT3: 783 | BU3: 656 | BV3: 1187 | BW3: 4 | BX3: 83 | BY3: 131 | BZ3: 325 | CA3: 188 | CB3: 702 | CC3: 123 | CD3: 409 | CE3: 577 | CF3: 922 | CG3: =BU3+BI3 -> 4216 | CH3: =BV3+BJ3 -> 5268 | CI3: =BW3+BK3 -> 5 | CJ3: =BX3+BL3 -> 97 | CK3: =BY3+BM3 -> 163 | CL3: =BZ3+BN3 -> 832 | CM3: =CA3+BO3 -> 312 | CN3: =CB3+BP3 -> 4537 | ... CR3: =CF3+BT3 -> 1705
A4: 1005 | B4: PRIZREN | C4: 147246 | D4: 115421 | E4: 7119 | F4: 15388 | G4: 16342 | H4: 640 | I4: 1273 | J4: 455 | K4: 1183 | L4: 1058 | M4: 588 | N4: 886 | O4: 929 | P4: 0 | Q4: 6 | R4: 19 | S4: 324 | T4: 60 | U4: 54 | V4: 0 | Y4: 45 | Z4: 59 | AA4: 0 | AB4: 0 | AC4: 0 | AD4: 0 | AE4: 0 | AF4: 0 | AG4: 0 | AH4: 0 | AI4: 0 | AJ4: 0 | AK4: 0 | AL4: =Z4+N4 -> 945 | AM4: =AA4+O4 -> 929 | AN4: =AB4+P4 -> 0 | AO4: =AC4+Q4 -> 6 | AP4: =AD4+R4 -> 19 | AQ4: =AE4+S4 -> 324 | AR4: =AF4+T4 -> 60 | AS4: =AG4+U4 -> 54 | ... AW4: =AK4+Y4 -> 45 | AX4: 16152 | AY4: 17301 | AZ4: 1743 | BA4: 811 | BB4: 427 | BC4: 1382 | BD4: 1062 | BE4: 589 | BF4: 17164 | BG4: 5983 | BH4: 630 | BI4: 851 | BJ4: 927 | BK4: 0 | BL4: 9 | BM4: 34 | BN4: 267 | BO4: 54 | BP4: 854 | BQ4: 62 | BR4: 587 | BS4: 365 | BT4: 86 | BU4: 54 | BV4: 100 | BW4: 0 | BX4: 0 | BY4: 9 | BZ4: 21 | CA4: 4 | CB4: 40 | CC4: 13 | CD4: 33 | CE4: 46 | CF4: 70 | CG4: =BU4+BI4 -> 905 | CH4: =BV4+BJ4 -> 1027 | CI4: =BW4+BK4 -> 0 | CJ4: =BX4+BL4 -> 9 | CK4: =BY4+BM4 -> 43 | CL4: =BZ4+BN4 -> 288 | CM4: =CA4+BO4 -> 58 | CN4: =CB4+BP4 -> 894 | ... CR4: =CF4+BT4 -> 156
A5: 1003 | B5: FERIZAJ | C5: 109255 | D5: 84228 | E5: 6371 | F5: 13031 | G5: 13869 | H5: 662 | I5: 655 | J5: 478 | K5: 1364 | L5: 1547 | M5: 947 | N5: 660 | O5: 693 | P5: 0 | Q5: 2 | R5: 13 | S5: 224 | T5: 80 | U5: 77 | V5: 0 | Y5: 43 | Z5: 69 | AA5: 0 | AB5: 0 | AC5: 0 | AD5: 0 | AE5: 0 | AF5: 0 | AG5: 0 | AH5: 0 | AI5: 0 | AJ5: 0 | AK5: 0 | AL5: =Z5+N5 -> 729 | AM5: =AA5+O5 -> 693 | AN5: =AB5+P5 -> 0 | AO5: =AC5+Q5 -> 2 | AP5: =AD5+R5 -> 13 | AQ5: =AE5+S5 -> 224 | AR5: =AF5+T5 -> 80 | AS5: =AG5+U5 -> 77 | ... AW5: =AK5+Y5 -> 43 | AX5: 13576 | AY5: 14478 | AZ5: 1527 | BA5: 331 | BB5: 538 | BC5: 1578 | BD5: 1585 | BE5: 992 | BF5: 13942 | BG5: 6284 | BH5: 820 | BI5: 651 | BJ5: 718 | BK5: 0 | BL5: 2 | BM5: 17 | BN5: 212 | BO5: 103 | BP5: 669 | BQ5: 80 | BR5: 561 | BS5: 432 | BT5: 75 | BU5: 75 | BV5: 133 | BW5: 0 | BX5: 0 | BY5: 11 | BZ5: 55 | CA5: 13 | CB5: 97 | CC5: 19 | CD5: 58 | CE5: 67 | CF5: 32 | CG5: =BU5+BI5 -> 726 | CH5: =BV5+BJ5 -> 851 | CI5: =BW5+BK5 -> 0 | CJ5: =BX5+BL5 -> 2 | CK5: =BY5+BM5 -> 28 | CL5: =BZ5+BN5 -> 267 | CM5: =CA5+BO5 -> 116 | CN5: =CB5+BP5 -> 766 | ... CR5: =CF5+BT5 -> 107
A6: 1006 | B6: PEJË | C6: 82745 | D6: 65980 | E6: 4172 | F6: 14551 | G6: 15571 | H6: 1067 | I6: 1100 | J6: 441 | K6: 1634 | L6: 1521 | M6: 945 | N6: 629 | O6: 659 | P6: 0 | Q6: 1 | R6: 11 | S6: 132 | T6: 52 | U6: 27 | V6: 0 | Y6: 92 | Z6: 72 | AA6: 7 | AB6: 0 | AC6: 0 | AD6: 0 | AE6: 2 | AF6: 0 | AG6: 0 | AH6: 0 | AI6: 0 | AJ6: 0 | AK6: 0 | AL6: =Z6+N6 -> 701 | AM6: =AA6+O6 -> 666 | AN6: =AB6+P6 -> 0 | AO6: =AC6+Q6 -> 1 | AP6: =AD6+R6 -> 11 | AQ6: =AE6+S6 -> 134 | AR6: =AF6+T6 -> 52 | AS6: =AG6+U6 -> 27 | ... AW6: =AK6+Y6 -> 92 | AX6: 15027 | AY6: 16412 | AZ6: 2512 | BA6: 524 | BB6: 434 | BC6: 1780 | BD6: 1545 | BE6: 990 | BF6: 15680 | BG6: 6557 | BH6: 709 | BI6: 628 | BJ6: 689 | BK6: 0 | BL6: 2 | BM6: 11 | BN6: 132 | BO6: 70 | BP6: 688 | BQ6: 34 | BR6: 500 | BS6: 252 | BT6: 150 | BU6: 70 | BV6: 160 | BW6: 0 | BX6: 0 | BY6: 12 | BZ6: 59 | CA6: 17 | CB6: 184 | CC6: 18 | CD6: 46 | CE6: 63 | CF6: 271 | CG6: =BU6+BI6 -> 698 | CH6: =BV6+BJ6 -> 849 | CI6: =BW6+BK6 -> 0 | CJ6: =BX6+BL6 -> 2 | CK6: =BY6+BM6 -> 23 | CL6: =BZ6+BN6 -> 191 | CM6: =CA6+BO6 -> 87 | CN6: =CB6+BP6 -> 872 | ... CR6: =CF6+BT6 -> 421
A7: 100104 | B7: FUSHË KOSOVË | C7: 63949 | D7: 47439 | E7: 2711 | F7: 6061 | G7: 6215 | H7: 367 | I7: 321 | J7: 256 | K7: 717 | L7: 746 | M7: 486 | N7: 461 | O7: 485 | P7: 0 | Q7: 3 | R7: 3 | S7: 132 | T7: 12 | U7: 10 | V7: 0 | Y7: 75 | Z7: 0 | AA7: 0 | AB7: 0 | AC7: 0 | AD7: 0 | AE7: 0 | AF7: 0 | AG7: 0 | AH7: 0 | AI7: 0 | AJ7: 0 | AK7: 0 | AL7: =Z7+N7 -> 461 | AM7: =AA7+O7 -> 485 | AN7: =AB7+P7 -> 0 | AO7: =AC7+Q7 -> 3 | AP7: =AD7+R7 -> 3 | AQ7: =AE7+S7 -> 132 | AR7: =AF7+T7 -> 12 | AS7: =AG7+U7 -> 10 | ... AW7: =AK7+Y7 -> 75 | AX7: 6301 | AY7: 6554 | AZ7: 782 | BA7: 134 | BB7: 287 | BC7: 914 | BD7: 754 | BE7: 474 | BF7: 6570 | BG7: 3527 | BH7: 468 | BI7: 489 | BJ7: 538 | BK7: 0 | BL7: 2 | BM7: 3 | BN7: 137 | BO7: 12 | BP7: 496 | BQ7: 15 | BR7: 418 | BS7: 275 | BT7: 78 | BU7: 42 | BV7: 74 | BW7: 0 | BX7: 0 | BY7: 8 | BZ7: 33 | CA7: 7 | CB7: 28 | CC7: 9 | CD7: 28 | CE7: 41 | CF7: 123 | CG7: =BU7+BI7 -> 531 | CH7: =BV7+BJ7 -> 612 | CI7: =BW7+BK7 -> 0 | CJ7: =BX7+BL7 -> 2 | CK7: =BY7+BM7 -> 11 | CL7: =BZ7+BN7 -> 170 | CM7: =CA7+BO7 -> 19 | CN7: =CB7+BP7 -> 524 | ... CR7: =CF7+BT7 -> 201
A8: 1004 | B8: GJAKOVË | C8: 78699 | D8: 62970 | E8: 4005 | F8: 8802 | G8: 9251 | H8: 568 | I8: 1085 | J8: 503 | K8: 1133 | L8: 817 | M8: 514 | N8: 475 | O8: 511 | P8: 0 | Q8: 2 | R8: 0 | S8: 139 | T8: 28 | U8: 10 | V8: 0 | Y8: 29 | Z8: 26 | AA8: 37 | AB8: 0 | AC8: 3 | AD8: 7 | AE8: 21 | AF8: 1 | AG8: 5 | AH8: 0 | AI8: 0 | AJ8: 0 | AK8: 4 | AL8: =Z8+N8 -> 501 | AM8: =AA8+O8 -> 548 | AN8: =AB8+P8 -> 0 | AO8: =AC8+Q8 -> 5 | AP8: =AD8+R8 -> 7 | AQ8: =AE8+S8 -> 160 | AR8: =AF8+T8 -> 29 | AS8: =AG8+U8 -> 15 | ... AW8: =AK8+Y8 -> 33 | AX8: 8812 | AY8: 9339 | AZ8: 1178 | BA8: 886 | BB8: 447 | BC8: 1229 | BD8: 845 | BE8: 512 | BF8: 9007 | BG8: 3312 | BH8: 381 | BI8: 408 | BJ8: 461 | BK8: 0 | BL8: 2 | BM8: 1 | BN8: 79 | BO8: 29 | BP8: 384 | BQ8: 15 | BR8: 281 | BS8: 148 | BT8: 44 | BU8: 23 | BV8: 44 | BW8: 0 | BX8: 4 | BY8: 8 | BZ8: 23 | CA8: 4 | CB8: 17 | CC8: 5 | CD8: 9 | CE8: 18 | CF8: 16 | CG8: =BU8+BI8 -> 431 | CH8: =BV8+BJ8 -> 505 | CI8: =BW8+BK8 -> 0 | CJ8: =BX8+BL8 -> 6 | CK8: =BY8+BM8 -> 9 | CL8: =BZ8+BN8 -> 102 | CM8: =CA8+BO8 -> 33 | CN8: =CB8+BP8 -> 401 | ... CR8: =CF8+BT8 -> 60
A9: 1007 | B9: MITROVICË | C9: 64742 | D9: 50171 | E9: 2529 | F9: 11839 | G9: 12652 | H9: 679 | I9: 954 | J9: 452 | K9: 994 | L9: 775 | M9: 410 | N9: 376 | O9: 389 | P9: 0 | Q9: 1 | R9: 6 | S9: 103 | T9: 26 | U9: 18 | V9: 0 | Y9: 39 | Z9: 24 | AA9: 0 | AB9: 0 | AC9: 0 | AD9: 0 | AE9: 0 | AF9: 0 | AG9: 0 | AH9: 0 | AI9: 0 | AJ9: 0 | AK9: 0 | AL9: =Z9+N9 -> 400 | AM9: =AA9+O9 -> 389 | AN9: =AB9+P9 -> 0 | AO9: =AC9+Q9 -> 1 | AP9: =AD9+R9 -> 6 | AQ9: =AE9+S9 -> 103 | AR9: =AF9+T9 -> 26 | AS9: =AG9+U9 -> 18 | ... AW9: =AK9+Y9 -> 39 | AX9: 11901 | AY9: 12833 | AZ9: 1897 | BA9: 417 | BB9: 482 | BC9: 1087 | BD9: 780 | BE9: 416 | BF9: 12659 | BG9: 4249 | BH9: 681 | BI9: 403 | BJ9: 439 | BK9: 0 | BL9: 0 | BM9: 6 | BN9: 106 | BO9: 45 | BP9: 398 | BQ9: 25 | BR9: 291 | BS9: 188 | BT9: 91 | BU9: 24 | BV9: 47 | BW9: 0 | BX9: 0 | BY9: 0 | BZ9: 9 | CA9: 4 | CB9: 22 | CC9: 4 | CD9: 19 | CE9: 19 | CF9: 16 | CG9: =BU9+BI9 -> 427 | CH9: =BV9+BJ9 -> 486 | CI9: =BW9+BK9 -> 0 | CJ9: =BX9+BL9 -> 0 | CK9: =BY9+BM9 -> 6 | CL9: =BZ9+BN9 -> 115 | CM9: =CA9+BO9 -> 49 | CN9: =CB9+BP9 -> 420 | ... CR9: =CF9+BT9 -> 107
A10: 100702 | B10: VUSHTRRI | C10: 61528 | D10: 47591 | E10: 1868 | F10: 6269 | G10: 6532 | H10: 323 | I10: 348 | J10: 170 | K10: 484 | L10: 395 | M10: 230 | N10: 188 | O10: 194 | P10: 0 | Q10: 0 | R10: 3 | S10: 73 | T10: 26 | U10: 22 | V10: 0 | Y10: 23 | Z10: 23 | AA10: 0 | AB10: 0 | AC10: 0 | AD10: 0 | AE10: 0 | AF10: 0 | AG10: 0 | AH10: 0 | AI10: 0 | AJ10: 0 | AK10: 0 | AL10: =Z10+N10 -> 211 | AM10: =AA10+O10 -> 194 | AN10: =AB10+P10 -> 0 | AO10: =AC10+Q10 -> 0 | AP10: =AD10+R10 -> 3 | AQ10: =AE10+S10 -> 73 | AR10: =AF10+T10 -> 26 | AS10: =AG10+U10 -> 22 | ... AW10: =AK10+Y10 -> 23 | AX10: 6504 | AY10: 6921 | AZ10: 828 | BA10: 118 | BB10: 180 | BC10: 610 | BD10: 406 | BE10: 250 | BF10: 6810 | BG10: 2447 | BH10: 253 | BI10: 191 | BJ10: 203 | BK10: 0 | BL10: 0 | BM10: 2 | BN10: 60 | BO10: 38 | BP10: 183 | BQ10: 17 | BR10: 159 | BS10: 62 | BT10: 33 | BU10: 20 | BV10: 35 | BW10: 0 | BX10: 0 | BY10: 5 | BZ10: 24 | CA10: 4 | CB10: 26 | CC10: 7 | CD10: 13 | CE10: 17 | CF10: 36 | CG10: =BU10+BI10 -> 211 | CH10: =BV10+BJ10 -> 238 | CI10: =BW10+BK10 -> 0 | CJ10: =BX10+BL10 -> 0 | CK10: =BY10+BM10 -> 7 | CL10: =BZ10+BN10 -> 84 | CM10: =CA10+BO10 -> 42 | CN10: =CB10+BP10 -> 209 | ... CR10: =CF10+BT10 -> 69
A11: 000103 | B11: GLLOGOC | C11: 48079 | D11: 36276 | E11: 1566 | F11: 8493 | G11: 8920 | H11: 366 | I11: 495 | J11: 350 | K11: 905 | L11: 1385 | M11: 908 | N11: 324 | O11: 325 | P11: 0 | Q11: 8 | R11: 10 | S11: 133 | T11: 57 | U11: 31 | V11: 0 | Y11: 32 | Z11: 28 | AA11: 0 | AB11: 0 | AC11: 0 | AD11: 0 | AE11: 0 | AF11: 0 | AG11: 0 | AH11: 0 | AI11: 0 | AJ11: 0 | AK11: 0 | AL11: =Z11+N11 -> 352 | AM11: =AA11+O11 -> 325 | AN11: =AB11+P11 -> 0 | AO11: =AC11+Q11 -> 8 | AP11: =AD11+R11 -> 10 | AQ11: =AE11+S11 -> 133 | AR11: =AF11+T11 -> 57 | AS11: =AG11+U11 -> 31 | ... AW11: =AK11+Y11 -> 32 | AX11: 8808 | AY11: 9389 | AZ11: 937 | BA11: 305 | BB11: 331 | BC11: 1091 | BD11: 1286 | BE11: 928 | BF11: 9310 | BG11: 4361 | BH11: 875 | BI11: 313 | BJ11: 324 | BK11: 0 | BL11: 4 | BM11: 8 | BN11: 115 | BO11: 50 | BP11: 325 | BQ11: 29 | BR11: 259 | BS11: 151 | BT11: 40 | BU11: 28 | BV11: 39 | BW11: 0 | BX11: 0 | BY11: 4 | BZ11: 14 | CA11: 8 | CB11: 34 | CC11: 7 | CD11: 21 | CE11: 26 | CF11: 38 | CG11: =BU11+BI11 -> 341 | CH11: =BV11+BJ11 -> 363 | CI11: =BW11+BK11 -> 0 | CJ11: =BX11+BL11 -> 4 | CK11: =BY11+BM11 -> 12 | CL11: =BZ11+BN11 -> 129 | CM11: =CA11+BO11 -> 58 | CN11: =CB11+BP11 -> 359 | ... CR11: =CF11+BT11 -> 78
A12: 1009 | B12: PODUJEVË | C12: 70975 | D12: 54812 | E12: 2381 | F12: 10092 | G12: 10305 | H12: 560 | I12: 485 | J12: 252 | K12: 666 | L12: 622 | M12: 235 | N12: 317 | O12: 321 | P12: 0 | Q12: 1 | R12: 6 | S12: 65 | T12: 30 | U12: 22 | V12: 0 | Y12: 17 | Z12: 30 | AA12: 0 | AB12: 0 | AC12: 0 | AD12: 0 | AE12: 0 | AF12: 0 | AG12: 0 | AH12: 0 | AI12: 0 | AJ12: 0 | AK12: 0 | AL12: =Z12+N12 -> 347 | AM12: =AA12+O12 -> 321 | AN12: =AB12+P12 -> 0 | AO12: =AC12+Q12 -> 1 | AP12: =AD12+R12 -> 6 | AQ12: =AE12+S12 -> 65 | AR12: =AF12+T12 -> 30 | AS12: =AG12+U12 -> 22 | ... AW12: =AK12+Y12 -> 17 | AX12: 10670 | AY12: 10968 | AZ12: 1089 | BA12: 377 | BB12: 243 | BC12: 768 | BD12: 756 | BE12: 319 | BF12: 11127 | BG12: 4666 | BH12: 608 | BI12: 320 | BJ12: 351 | BK12: 0 | BL12: 1 | BM12: 4 | BN12: 67 | BO12: 20 | BP12: 343 | BQ12: 18 | BR12: 249 | BS12: 148 | BT12: 35 | BU12: 29 | BV12: 55 | BW12: 0 | BX12: 0 | BY12: 12 | BZ12: 27 | CA12: 4 | CB12: 44 | CC12: 12 | CD12: 19 | CE12: 28 | CF12: 10 | CG12: =BU12+BI12 -> 349 | CH12: =BV12+BJ12 -> 406 | CI12: =BW12+BK12 -> 0 | CJ12: =BX12+BL12 -> 1 | CK12: =BY12+BM12 -> 16 | CL12: =BZ12+BN12 -> 94 | CM12: =CA12+BO12 -> 24 | CN12: =CB12+BP12 -> 387 | ... CR12: =CF12+BT12 -> 45
A13: 100106 | B13: LIPJAN | C13: 55044 | D13: 41804 | E13: 1874 | F13: 5716 | G13: 5950 | H13: 167 | I13: 247 | J13: 178 | K13: 554 | L13: 581 | M13: 340 | N13: 316 | O13: 335 | P13: 0 | Q13: 1 | R13: 5 | S13: 114 | T13: 58 | U13: 28 | V13: 0 | Y13: 29 | Z13: 41 | AA13: 0 | AB13: 0 | AC13: 0 | AD13: 0 | AE13: 0 | AF13: 0 | AG13: 0 | AH13: 0 | AI13: 0 | AJ13: 0 | AK13: 0 | AL13: =Z13+N13 -> 357 | AM13: =AA13+O13 -> 335 | AN13: =AB13+P13 -> 0 | AO13: =AC13+Q13 -> 1 | AP13: =AD13+R13 -> 5 | AQ13: =AE13+S13 -> 114 | AR13: =AF13+T13 -> 58 | AS13: =AG13+U13 -> 28 | ... AW13: =AK13+Y13 -> 29 | AX13: 5950 | AY13: 6269 | AZ13: 448 | BA13: 115 | BB13: 191 | BC13: 701 | BD13: 632 | BE13: 371 | BF13: 6234 | BG13: 2469 | BH13: 306 | BI13: 310 | BJ13: 369 | BK13: 0 | BL13: 1 | BM13: 6 | BN13: 108 | BO13: 60 | BP13: 313 | BQ13: 31 | BR13: 259 | BS13: 127 | BT13: 61 | BU13: 43 | BV13: 74 | BW13: 0 | BX13: 0 | BY13: 10 | BZ13: 32 | CA13: 11 | CB13: 53 | CC13: 13 | CD13: 36 | CE13: 38 | CF13: 65 | CG13: =BU13+BI13 -> 353 | CH13: =BV13+BJ13 -> 443 | CI13: =BW13+BK13 -> 0 | CJ13: =BX13+BL13 -> 1 | CK13: =BY13+BM13 -> 16 | CL13: =BZ13+BN13 -> 140 | CM13: =CA13+BO13 -> 71 | CN13: =CB13+BP13 -> 366 | ... CR13: =CF13+BT13 -> 126
A14: 1002 | B14: GJILAN | C14: 82980 | D14: 66517 | E14: 4317 | F14: 11191 | G14: 11714 | H14: 626 | I14: 620 | J14: 591 | K14: 1274 | L14: 1159 | M14: 732 | N14: 388 | O14: 413 | P14: 0 | Q14: 2 | R14: 3 | S14: 126 | T14: 34 | U14: 16 | V14: 0 | Y14: 49 | Z14: 51 | AA14: 0 | AB14: 0 | AC14: 2 | AD14: 0 | AE14: 0 | AF14: 0 | AG14: 0 | AH14: 0 | AI14: 0 | AJ14: 0 | AK14: 0 | AL14: =Z14+N14 -> 439 | AM14: =AA14+O14 -> 413 | AN14: =AB14+P14 -> 0 | AO14: =AC14+Q14 -> 4 | AP14: =AD14+R14 -> 3 | AQ14: =AE14+S14 -> 126 | AR14: =AF14+T14 -> 34 | AS14: =AG14+U14 -> 16 | ... AW14: =AK14+Y14 -> 49 | AX14: 11535 | AY14: 12234 | AZ14: 1303 | BA14: 377 | BB14: 670 | BC14: 1439 | BD14: 1216 | BE14: 773 | BF14: 11919 | BG14: 5574 | BH14: 565 | BI14: 405 | BJ14: 451 | BK14: 0 | BL14: 2 | BM14: 3 | BN14: 124 | BO14: 37 | BP14: 409 | BQ14: 24 | BR14: 361 | BS14: 195 | BT14: 83 | BU14: 54 | BV14: 82 | BW14: 0 | BX14: 3 | BY14: 6 | BZ14: 33 | CA14: 12 | CB14: 34 | CC14: 12 | CD14: 49 | CE14: 46 | CF14: 32 | CG14: =BU14+BI14 -> 459 | CH14: =BV14+BJ14 -> 533 | CI14: =BW14+BK14 -> 0 | CJ14: =BX14+BL14 -> 5 | CK14: =BY14+BM14 -> 9 | CL14: =BZ14+BN14 -> 157 | CM14: =CA14+BO14 -> 49 | CN14: =CB14+BP14 -> 443 | ... CR14: =CF14+BT14 -> 115
... A40: Ska degë | B40: RANILLUG | C40: 2481 | D40: 2078 | E40: 35 | F40: 0 | G40: 0 | H40: 0 | I40: 0 | J40: 0 | K40: 0 | L40: 0 | M40: 0 | N40: 0 | O40: 0 | P40: 0 | Q40: 0 | R40: 0 | S40: 0 | T40: 0 | U40: 0 | V40: 0 | Y40: 0 | Z40: 0 | AA40: 0 | AB40: 0 | AC40: 0 | AD40: 0 | AE40: 0 | AF40: 0 | AG40: 0 | AH40: 0 | AI40: 0 | AJ40: 0 | AK40: 0 | AL40: =Z40+N40 -> 0 | AM40: =AA40+O40 -> 0 | AN40: =AB40+P40 -> 0 | AO40: =AC40+Q40 -> 0 | AP40: =AD40+R40 -> 0 | AQ40: =AE40+S40 -> 0 | AR40: =AF40+T40 -> 0 | AS40: =AG40+U40 -> 0 | ... AW40: =AK40+Y40 -> 0 | AX40: 0 | AY40: 0 | AZ40: 0 | BA40: 0 | BB40: 0 | BC40: 0 | BD40: 0 | BE40: 0 | BF40: 0 | BG40: 0 | BH40: 0 | BI40: 0 | BJ40: 0 | BK40: 0 | BL40: 0 | BM40: 0 | BN40: 0 | BO40: 0 | BP40: 0 | BQ40: 0 | BR40: 0 | BS40: 0 | BT40: 0 | BU40: 0 | BV40: 0 | BW40: 0 | BX40: 0 | BY40: 0 | BZ40: 0 | CA40: 0 | CB40: 0 | CC40: 0 | CD40: 0 | CE40: 0 | CF40: 0 | CG40: =BU40+BI40 -> 0 | CH40: =BV40+BJ40 -> 0 | CI40: =BW40+BK40 -> 0 | CJ40: =BX40+BL40 -> 0 | CK40: =BY40+BM40 -> 0 | CL40: =BZ40+BN40 -> 0 | CM40: =CA40+BO40 -> 0 | CN40: =CB40+BP40 -> 0 | ... CR40: =CF40+BT40 -> 0
B41: Total | C41: =SUM(C3:C40) -> 1602515 | D41: =SUM(D3:D40) -> 1252619 | E41: =SUM(E3:E40) -> 77712 | F41: =SUM(F3:F40) -> 231116 | G41: =SUM(G3:G40) -> 243503 | H41: =SUM(H3:H40) -> 13791 | I41: =SUM(I3:I40) -> 15274 | J41: =SUM(J3:J40) -> 9177 | ... V41: =SUM(V3:V40) -> 0 | Y41: =SUM(Y3:Y40) -> 1250 | Z41: =SUM(Z3:Z40) -> 1261 | AA41: =SUM(AA3:AA40) -> 150 | AB41: =SUM(AB3:AB40) -> 0 | AC41: =SUM(AC3:AC40) -> 73 | AD41: =SUM(AD3:AD40) -> 26 | AE41: =SUM(AE3:AE40) -> 54 | AF41: =SUM(AF3:AF40) -> 16 | ... AH41: =SUM(AH3:AH40) -> 0 | AK41: =SUM(AK3:AK40) -> 157 | AL41: =SUM(AL3:AL40) -> 12888 | AM41: =SUM(AM3:AM40) -> 12438 | AN41: =SUM(AN3:AN40) -> 0 | AO41: =SUM(AO3:AO40) -> 111 | AP41: =SUM(AP3:AP40) -> 175 | AQ41: =SUM(AQ3:AQ40) -> 2969 | AR41: =SUM(AR3:AR40) -> 834 | ... AT41: =SUM(AT3:AT40) -> 0 | AW41: =SUM(AW3:AW40) -> 1407 | AX41: =SUM(AX3:AX40) -> 240157 | AY41: =SUM(AY3:AY40) -> 256209 | AZ41: =SUM(AZ3:AZ40) -> 30615 | BA41: =SUM(BA3:BA40) -> 8647 | BB41: =SUM(BB3:BB40) -> 9381 | BC41: =SUM(BC3:BC40) -> 27260 | BD41: =SUM(BD3:BD40) -> 24107 | ... CR41: =SUM(CR3:CR40) -> 3819

Sheet Clients PI
E1: 2025 | F1: 2026 | G1: DIFF | I1: Active Client vs Population
A2: Branch | B2: Branch/City | C2: Popullsia | D2: Pop >15 | E2: Active Clients | F2: Active Clients | G2: Clients No | H2: Clients % | I2: 2025 | J2: 2026
A3: 100703 | B3: MITROVICË VERIORE | C3: 7920 | D3: 6833 | E3: 9307 | F3: 9261 | G3: =F3-E3 -> -46 | H3: =G3/E3 -> -0.0049425164 | I3: =E3/D3 -> 1.3620664 | J3: =F3/D3 -> 1.3553344
A4: 100301 | B4: HANI I ELEZIT | C4: 8533 | D4: 6447 | E4: 3155 | F4: 3424 | G4: =F4-E4 -> 269 | H4: =G4/E4 -> 0.08526149 | I4: =E4/D4 -> 0.4893749 | J4: =F4/D4 -> 0.53109974
A5: 100604 | B5: DEÇAN | C5: 27775 | D5: 22138 | E5: 7374 | F5: 7529 | G5: =F5-E5 -> 155 | H5: =G5/E5 -> 0.021019799 | I5: =E5/D5 -> 0.33309242 | J5: =F5/D5 -> 0.34009396
A6: 100303 | B6: SHTËRPCË | C6: 10771 | D6: 9026 | E6: 2881 | F6: 2976 | G6: =F6-E6 -> 95 | H6: =G6/E6 -> 0.032974662 | I6: =E6/D6 -> 0.31918901 | J6: =F6/D6 -> 0.32971416
A7: 100302 | B7: KAÇANIK | C7: 27716 | D7: 21269 | E7: 5730 | F7: 5947 | G7: =F7-E7 -> 217 | H7: =G7/E7 -> 0.037870855 | I7: =E7/D7 -> 0.26940618 | J7: =F7/D7 -> 0.27960882
A8: 0001 | B8: PRISHTINË | C8: 227466 | D8: 177302 | E8: 45420 | F8: 47635 | G8: =F8-E8 -> 2215 | H8: =G8/E8 -> 0.048767063 | I8: =E8/D8 -> 0.25617308 | J8: =F8/D8 -> 0.26866589
A9: 100108 | B9: GRAÇANICË | C9: 18486 | D9: 14806 | E9: 3610 | F9: 3691 | G9: =F9-E9 -> 81 | H9: =G9/E9 -> 0.022437673 | I9: =E9/D9 -> 0.24382007 | J9: =F9/D9 -> 0.24929083
A10: 000103 | B10: GLLOGOC | C10: 48079 | D10: 36276 | E10: 8493 | F10: 8808 | G10: =F10-E10 -> 315 | H10: =G10/E10 -> 0.037089368 | I10: =E10/D10 -> 0.23412173 | J10: =F10/D10 -> 0.24280516
A11: 100105 | B11: OBILIQ | C11: 22815 | D11: 17367 | E11: 3945 | F11: 4126 | G11: =F11-E11 -> 181 | H11: =G11/E11 -> 0.045880862 | I11: =E11/D11 -> 0.22715495 | J11: =F11/D11 -> 0.23757701
A12: 1007 | B12: MITROVICË | C12: 64742 | D12: 50171 | E12: 11839 | F12: 11901 | G12: =F12-E12 -> 62 | H12: =G12/E12 -> 0.0052369288 | I12: =E12/D12 -> 0.23597297 | J12: =F12/D12 -> 0.23720875
A13: 1006 | B13: PEJË | C13: 82745 | D13: 65980 | E13: 14551 | F13: 15027 | G13: =F13-E13 -> 476 | H13: =G13/E13 -> 0.032712528 | I13: =E13/D13 -> 0.22053653 | J13: =F13/D13 -> 0.22775083
A14: 1009 | B14: PODUJEVË | C14: 70975 | D14: 54812 | E14: 10092 | F14: 10670 | G14: =F14-E14 -> 578 | H14: =G14/E14 -> 0.057273088 | I14: =E14/D14 -> 0.18412027 | J14: =F14/D14 -> 0.1946654
... A31: 100705 | B31: LEPOSAVIQ | C31: 9485 | D31: 8435 | E31: 193 | F31: 389 | G31: =F31-E31 -> 196 | H31: =G31/E31 -> 1.015544 | I31: =E31/D31 -> 0.022880854 | J31: =F31/D31 -> 0.046117368
A32: Ska degë | B32: SHTIME | C32: 24308 | D32: 18586 | E32: 0 | F32: 0 | G32: =F32-E32 -> 0 | I32: =E32/D32 -> 0 | J32: =F32/D32 -> 0
A33: Ska degë | B33: DRAGASH | C33: 28896 | D33: 23559 | E33: 0 | F33: 0 | G33: =F33-E33 -> 0 | I33: =E33/D33 -> 0 | J33: =F33/D33 -> 0
A34: Ska degë | B34: MAMUSHË | C34: 5607 | D34: 4206 | E34: 0 | F34: 0 | G34: =F34-E34 -> 0 | I34: =E34/D34 -> 0 | J34: =F34/D34 -> 0
A35: Ska degë | B35: KLLOKOT | C35: 3041 | D35: 2409 | E35: 0 | F35: 0 | G35: =F35-E35 -> 0 | I35: =E35/D35 -> 0 | J35: =F35/D35 -> 0
A36: Ska degë | B36: NOVOBËRDË | C36: 4493 | D36: 3426 | E36: 0 | F36: 0 | G36: =F36-E36 -> 0 | I36: =E36/D36 -> 0 | J36: =F36/D36 -> 0
A37: Ska degë | B37: JUNIK | C37: 3943 | D37: 3266 | E37: 0 | F37: 0 | G37: =F37-E37 -> 0 | I37: =E37/D37 -> 0 | J37: =F37/D37 -> 0
A38: Ska degë | B38: PARTESH | C38: 3240 | D38: 2762 | E38: 0 | F38: 0 | G38: =F38-E38 -> 0 | I38: =E38/D38 -> 0 | J38: =F38/D38 -> 0
A39: Ska degë | B39: ZVEÇAN | C39: 2867 | D39: 2490 | E39: 0 | F39: 0 | G39: =F39-E39 -> 0 | I39: =E39/D39 -> 0 | J39: =F39/D39 -> 0
A40: Ska degë | B40: RANILLUG | C40: 2481 | D40: 2078 | E40: 0 | F40: 0 | G40: =F40-E40 -> 0 | I40: =E40/D40 -> 0 | J40: =F40/D40 -> 0
B41: Total | C41: =SUM(C3:C40) -> 1602515 | D41: =SUM(D3:D40) -> 1252619 | E41: 231116 | F41: =SUM(F3:F40) -> 240157 | G41: =SUM(G3:G40) -> 9041 | H41: =G41/E41 -> 0.039118884 | I41: =E41/D41 -> 0.18450622 | J41: =F41/D41 -> 0.1917239

Sheet CA PI
G1: 2025 | H1: 2026 | I1: Diff
A2: Branch | B2: Branch/City | C2: Popullsia | D2: Pop >15 | E2: Active Clients 2025 | F2: Active Clients 2026 | G2: CA | H2: CA | I2: 2025 CA vs Population | J2: 2025 CA vs Population | K2: 2025 vs 2026 NO | L2: 2025 vs 2026 | M2: CA per Active Clients 2025 | N2: CA per Active Clients 2026
A3: 100703 | B3: MITROVICË VERIORE | C3: 7920 | D3: 6833 | E3: 9307 | F3: 9261 | G3: =_xlfn.XLOOKUP(B3,Total!B:B,Total!G:G) -> 9715 | H3: =_xlfn.XLOOKUP(B3,Total!B:B,Total!AY:AY) -> 9699 | I3: =G3/D3 -> 1.4217767 | J3: =H3/D3 -> 1.4194351 | K3: =H3-G3 -> -16 | L3: =(H3-G3)/G3 -> -0.0016469377 | M3: =G3/E3 -> 1.043838 | N3: =H3/F3 -> 1.0472951
A4: 100301 | B4: HANI I ELEZIT | C4: 8533 | D4: 6447 | E4: 3155 | F4: 3424 | G4: =_xlfn.XLOOKUP(B4,Total!B:B,Total!G:G) -> 3271 | H4: =_xlfn.XLOOKUP(B4,Total!B:B,Total!AY:AY) -> 3567 | I4: =G4/D4 -> 0.50736777 | J4: =H4/D4 -> 0.5532806 | K4: =H4-G4 -> 296 | L4: =(H4-G4)/G4 -> 0.090492204 | M4: =G4/E4 -> 1.036767 | N4: =H4/F4 -> 1.041764
A5: 100303 | B5: SHTËRPCË | C5: 10771 | D5: 9026 | E5: 2881 | F5: 2976 | G5: =_xlfn.XLOOKUP(B5,Total!B:B,Total!G:G) -> 3175 | H5: =_xlfn.XLOOKUP(B5,Total!B:B,Total!AY:AY) -> 3276 | I5: =G5/D5 -> 0.35176158 | J5: =H5/D5 -> 0.36295147 | K5: =H5-G5 -> 101 | L5: =(H5-G5)/G5 -> 0.031811024 | M5: =G5/E5 -> 1.1020479 | N5: =H5/F5 -> 1.1008065
A6: 100604 | B6: DEÇAN | C6: 27775 | D6: 22138 | E6: 7374 | F6: 7529 | G6: =_xlfn.XLOOKUP(B6,Total!B:B,Total!G:G) -> 7598 | H6: =_xlfn.XLOOKUP(B6,Total!B:B,Total!AY:AY) -> 7861 | I6: =G6/D6 -> 0.34321077 | J6: =H6/D6 -> 0.35509079 | K6: =H6-G6 -> 263 | L6: =(H6-G6)/G6 -> 0.034614372 | M6: =G6/E6 -> 1.030377 | N6: =H6/F6 -> 1.0440962
A7: 0001 | B7: PRISHTINË | C7: 227466 | D7: 177302 | E7: 45420 | F7: 47635 | G7: =_xlfn.XLOOKUP(B7,Total!B:B,Total!G:G) -> 48925 | H7: =_xlfn.XLOOKUP(B7,Total!B:B,Total!AY:AY) -> 52720 | I7: =G7/D7 -> 0.27594161 | J7: =H7/D7 -> 0.29734577 | K7: =H7-G7 -> 3795 | L7: =(H7-G7)/G7 -> 0.077567706 | M7: =G7/E7 -> 1.0771686 | N7: =H7/F7 -> 1.1067492
A8: 100302 | B8: KAÇANIK | C8: 27716 | D8: 21269 | E8: 5730 | F8: 5947 | G8: =_xlfn.XLOOKUP(B8,Total!B:B,Total!G:G) -> 5947 | H8: =_xlfn.XLOOKUP(B8,Total!B:B,Total!AY:AY) -> 6181 | I8: =G8/D8 -> 0.27960882 | J8: =H8/D8 -> 0.29061075 | K8: =H8-G8 -> 234 | L8: =(H8-G8)/G8 -> 0.03934757 | M8: =G8/E8 -> 1.0378709 | N8: =H8/F8 -> 1.0393476
A9: 000103 | B9: GLLOGOC | C9: 48079 | D9: 36276 | E9: 8493 | F9: 8808 | G9: =_xlfn.XLOOKUP(B9,Total!B:B,Total!G:G) -> 8920 | H9: =_xlfn.XLOOKUP(B9,Total!B:B,Total!AY:AY) -> 9389 | I9: =G9/D9 -> 0.2458926 | J9: =H9/D9 -> 0.25882126 | K9: =H9-G9 -> 469 | L9: =(H9-G9)/G9 -> 0.052578475 | M9: =G9/E9 -> 1.0502767 | N9: =H9/F9 -> 1.0659628
A10: 100108 | B10: GRAÇANICË | C10: 18486 | D10: 14806 | E10: 3610 | F10: 3691 | G10: =_xlfn.XLOOKUP(B10,Total!B:B,Total!G:G) -> 3717 | H10: =_xlfn.XLOOKUP(B10,Total!B:B,Total!AY:AY) -> 3818 | I10: =G10/D10 -> 0.25104687 | J10: =H10/D10 -> 0.25786843 | K10: =H10-G10 -> 101 | L10: =(H10-G10)/G10 -> 0.027172451 | M10: =G10/E10 -> 1.0296399 | N10: =H10/F10 -> 1.034408
A11: 1007 | B11: MITROVICË | C11: 64742 | D11: 50171 | E11: 11839 | F11: 11901 | G11: =_xlfn.XLOOKUP(B11,Total!B:B,Total!G:G) -> 12652 | H11: =_xlfn.XLOOKUP(B11,Total!B:B,Total!AY:AY) -> 12833 | I11: =G11/D11 -> 0.25217755 | J11: =H11/D11 -> 0.25578521 | K11: =H11-G11 -> 181 | L11: =(H11-G11)/G11 -> 0.014306039 | M11: =G11/E11 -> 1.0686713 | N11: =H11/F11 -> 1.0783127
A12: 100105 | B12: OBILIQ | C12: 22815 | D12: 17367 | E12: 3945 | F12: 4126 | G12: =_xlfn.XLOOKUP(B12,Total!B:B,Total!G:G) -> 4163 | H12: =_xlfn.XLOOKUP(B12,Total!B:B,Total!AY:AY) -> 4398 | I12: =G12/D12 -> 0.23970749 | J12: =H12/D12 -> 0.2532389 | K12: =H12-G12 -> 235 | L12: =(H12-G12)/G12 -> 0.056449676 | M12: =G12/E12 -> 1.0552598 | N12: =H12/F12 -> 1.0659234
A13: 1006 | B13: PEJË | C13: 82745 | D13: 65980 | E13: 14551 | F13: 15027 | G13: =_xlfn.XLOOKUP(B13,Total!B:B,Total!G:G) -> 15571 | H13: =_xlfn.XLOOKUP(B13,Total!B:B,Total!AY:AY) -> 16412 | I13: =G13/D13 -> 0.23599576 | J13: =H13/D13 -> 0.24874204 | K13: =H13-G13 -> 841 | L13: =(H13-G13)/G13 -> 0.054010661 | M13: =G13/E13 -> 1.0700983 | N13: =H13/F13 -> 1.0921674
A14: 1009 | B14: PODUJEVË | C14: 70975 | D14: 54812 | E14: 10092 | F14: 10670 | G14: =_xlfn.XLOOKUP(B14,Total!B:B,Total!G:G) -> 10305 | H14: =_xlfn.XLOOKUP(B14,Total!B:B,Total!AY:AY) -> 10968 | I14: =G14/D14 -> 0.18800628 | J14: =H14/D14 -> 0.20010217 | K14: =H14-G14 -> 663 | L14: =(H14-G14)/G14 -> 0.0643377 | M14: =G14/E14 -> 1.0211058 | N14: =H14/F14 -> 1.0279288
... A31: 100705 | B31: LEPOSAVIQ | C31: 9485 | D31: 8435 | E31: 193 | F31: 389 | G31: =_xlfn.XLOOKUP(B31,Total!B:B,Total!G:G) -> 207 | H31: =_xlfn.XLOOKUP(B31,Total!B:B,Total!AY:AY) -> 418 | I31: =G31/D31 -> 0.024540605 | J31: =H31/D31 -> 0.049555424 | K31: =H31-G31 -> 211 | L31: =(H31-G31)/G31 -> 1.0193237 | M31: =G31/E31 -> 1.0725389 | N31: =H31/F31 -> 1.0745501
A32: Ska degë | B32: SHTIME | C32: 24308 | D32: 18586 | E32: 0 | F32: 0 | G32: =_xlfn.XLOOKUP(B32,Total!B:B,Total!G:G) -> 0 | H32: =_xlfn.XLOOKUP(B32,Total!B:B,Total!AY:AY) -> 0 | I32: =G32/D32 -> 0 | J32: =H32/D32 -> 0 | K32: =H32-G32 -> 0
A33: Ska degë | B33: DRAGASH | C33: 28896 | D33: 23559 | E33: 0 | F33: 0 | G33: =_xlfn.XLOOKUP(B33,Total!B:B,Total!G:G) -> 0 | H33: =_xlfn.XLOOKUP(B33,Total!B:B,Total!AY:AY) -> 0 | I33: =G33/D33 -> 0 | J33: =H33/D33 -> 0 | K33: =H33-G33 -> 0
A34: Ska degë | B34: MAMUSHË | C34: 5607 | D34: 4206 | E34: 0 | F34: 0 | G34: =_xlfn.XLOOKUP(B34,Total!B:B,Total!G:G) -> 0 | H34: =_xlfn.XLOOKUP(B34,Total!B:B,Total!AY:AY) -> 0 | I34: =G34/D34 -> 0 | J34: =H34/D34 -> 0 | K34: =H34-G34 -> 0
A35: Ska degë | B35: KLLOKOT | C35: 3041 | D35: 2409 | E35: 0 | F35: 0 | G35: =_xlfn.XLOOKUP(B35,Total!B:B,Total!G:G) -> 0 | H35: =_xlfn.XLOOKUP(B35,Total!B:B,Total!AY:AY) -> 0 | I35: =G35/D35 -> 0 | J35: =H35/D35 -> 0 | K35: =H35-G35 -> 0
A36: Ska degë | B36: NOVOBËRDË | C36: 4493 | D36: 3426 | E36: 0 | F36: 0 | G36: =_xlfn.XLOOKUP(B36,Total!B:B,Total!G:G) -> 0 | H36: =_xlfn.XLOOKUP(B36,Total!B:B,Total!AY:AY) -> 0 | I36: =G36/D36 -> 0 | J36: =H36/D36 -> 0 | K36: =H36-G36 -> 0
A37: Ska degë | B37: JUNIK | C37: 3943 | D37: 3266 | E37: 0 | F37: 0 | G37: =_xlfn.XLOOKUP(B37,Total!B:B,Total!G:G) -> 0 | H37: =_xlfn.XLOOKUP(B37,Total!B:B,Total!AY:AY) -> 0 | I37: =G37/D37 -> 0 | J37: =H37/D37 -> 0 | K37: =H37-G37 -> 0
A38: Ska degë | B38: PARTESH | C38: 3240 | D38: 2762 | E38: 0 | F38: 0 | G38: =_xlfn.XLOOKUP(B38,Total!B:B,Total!G:G) -> 0 | H38: =_xlfn.XLOOKUP(B38,Total!B:B,Total!AY:AY) -> 0 | I38: =G38/D38 -> 0 | J38: =H38/D38 -> 0 | K38: =H38-G38 -> 0
A39: Ska degë | B39: ZVEÇAN | C39: 2867 | D39: 2490 | E39: 0 | F39: 0 | G39: =_xlfn.XLOOKUP(B39,Total!B:B,Total!G:G) -> 0 | H39: =_xlfn.XLOOKUP(B39,Total!B:B,Total!AY:AY) -> 0 | I39: =G39/D39 -> 0 | J39: =H39/D39 -> 0 | K39: =H39-G39 -> 0
A40: Ska degë | B40: RANILLUG | C40: 2481 | D40: 2078 | E40: 0 | F40: 0 | G40: =_xlfn.XLOOKUP(B40,Total!B:B,Total!G:G) -> 0 | H40: =_xlfn.XLOOKUP(B40,Total!B:B,Total!AY:AY) -> 0 | I40: =G40/D40 -> 0 | J40: =H40/D40 -> 0 | K40: =H40-G40 -> 0
B41: Total | C41: =SUM(C3:C40) -> 1602515 | D41: =SUM(D3:D40) -> 1252619 | E41: =SUM(E3:E40) -> 231116 | F41: =SUM(F3:F40) -> 240157 | G41: =SUM(G3:G40) -> 243503 | H41: =SUM(H3:H40) -> 256209 | I41: =G41/D41 -> 0.1943951 | J41: =H41/D41 -> 0.20453865 | K41: =SUM(K1:K40) -> 12706 | L41: =(H41-G41)/G41 -> 0.052180055 | M41: =G41/E41 -> 1.0535965 | N41: =H41/F41 -> 1.0668396

Sheet TDA PI
G1: 2025 | H1: 2026 | I1: Diff
A2: Branch | B2: Branch/City | C2: Popullsia | D2: Pop >15 | E2: Active Clients 2025 | F2: Active Clients 2026 | G2: TDA | H2: TDA | I2: 2025 TDA vs Population | J2: 2025 TDA vs Population | K2: 2025 vs 2026 NO | L2: 2025 vs 2026 | M2: TDA per Active Clients 2025 | N2: TDA per Active Clients 2026
A3: 100703 | B3: MITROVICË VERIORE | C3: 7920 | D3: 6833 | E3: 9307 | F3: 9261 | G3: =_xlfn.XLOOKUP(B3,Total!B:B,Total!I:I) -> 333 | H3: =_xlfn.XLOOKUP(B3,Total!B:B,Total!BA:BA) -> 48 | I3: =G3/D3 -> 0.048734085 | J3: =H3/D3 -> 0.0070247329 | K3: =H3-G3 -> -285 | L3: =(H3-G3)/G3 -> -0.85585586 | M3: =G3/E3 -> 0.035779521 | N3: =H3/F3 -> 0.0051830256
A4: 100301 | B4: HANI I ELEZIT | C4: 8533 | D4: 6447 | E4: 3155 | F4: 3424 | G4: =_xlfn.XLOOKUP(B4,Total!B:B,Total!I:I) -> 143 | H4: =_xlfn.XLOOKUP(B4,Total!B:B,Total!BA:BA) -> 49 | I4: =G4/D4 -> 0.022180859 | J4: =H4/D4 -> 0.0076004343 | K4: =H4-G4 -> -94 | L4: =(H4-G4)/G4 -> -0.65734266 | M4: =G4/E4 -> 0.045324881 | N4: =H4/F4 -> 0.014310748
A5: 100303 | B5: SHTËRPCË | C5: 10771 | D5: 9026 | E5: 2881 | F5: 2976 | G5: =_xlfn.XLOOKUP(B5,Total!B:B,Total!I:I) -> 54 | H5: =_xlfn.XLOOKUP(B5,Total!B:B,Total!BA:BA) -> 31 | I5: =G5/D5 -> 0.0059827166 | J5: =H5/D5 -> 0.0034345225 | K5: =H5-G5 -> -23 | L5: =(H5-G5)/G5 -> -0.42592593 | M5: =G5/E5 -> 0.018743492 | N5: =H5/F5 -> 0.010416667
A6: 100604 | B6: DEÇAN | C6: 27775 | D6: 22138 | E6: 7374 | F6: 7529 | G6: =_xlfn.XLOOKUP(B6,Total!B:B,Total!I:I) -> 437 | H6: =_xlfn.XLOOKUP(B6,Total!B:B,Total!BA:BA) -> 375 | I6: =G6/D6 -> 0.019739814 | J6: =H6/D6 -> 0.0169392 | K6: =H6-G6 -> -62 | L6: =(H6-G6)/G6 -> -0.14187643 | M6: =G6/E6 -> 0.059262273 | N6: =H6/F6 -> 0.049807411
A7: 0001 | B7: PRISHTINË | C7: 227466 | D7: 177302 | E7: 45420 | F7: 47635 | G7: =_xlfn.XLOOKUP(B7,Total!B:B,Total!I:I) -> 4391 | H7: =_xlfn.XLOOKUP(B7,Total!B:B,Total!BA:BA) -> 2444 | I7: =G7/D7 -> 0.024765654 | J7: =H7/D7 -> 0.01378439 | K7: =H7-G7 -> -1947 | L7: =(H7-G7)/G7 -> -0.44340697 | M7: =G7/E7 -> 0.096675473 | N7: =H7/F7 -> 0.051306812
A8: 100302 | B8: KAÇANIK | C8: 27716 | D8: 21269 | E8: 5730 | F8: 5947 | G8: =_xlfn.XLOOKUP(B8,Total!B:B,Total!I:I) -> 261 | H8: =_xlfn.XLOOKUP(B8,Total!B:B,Total!BA:BA) -> 88 | I8: =G8/D8 -> 0.012271381 | J8: =H8/D8 -> 0.0041374771 | K8: =H8-G8 -> -173 | L8: =(H8-G8)/G8 -> -0.66283525 | M8: =G8/E8 -> 0.045549738 | N8: =H8/F8 -> 0.014797377
A9: 000103 | B9: GLLOGOC | C9: 48079 | D9: 36276 | E9: 8493 | F9: 8808 | G9: =_xlfn.XLOOKUP(B9,Total!B:B,Total!I:I) -> 495 | H9: =_xlfn.XLOOKUP(B9,Total!B:B,Total!BA:BA) -> 305 | I9: =G9/D9 -> 0.013645385 | J9: =H9/D9 -> 0.0084077627 | K9: =H9-G9 -> -190 | L9: =(H9-G9)/G9 -> -0.38383838 | M9: =G9/E9 -> 0.058283292 | N9: =H9/F9 -> 0.034627611
A10: 100108 | B10: GRAÇANICË | C10: 18486 | D10: 14806 | E10: 3610 | F10: 3691 | G10: =_xlfn.XLOOKUP(B10,Total!B:B,Total!I:I) -> 97 | H10: =_xlfn.XLOOKUP(B10,Total!B:B,Total!BA:BA) -> 42 | I10: =G10/D10 -> 0.0065513981 | J10: =H10/D10 -> 0.0028366878 | K10: =H10-G10 -> -55 | L10: =(H10-G10)/G10 -> -0.56701031 | M10: =G10/E10 -> 0.026869806 | N10: =H10/F10 -> 0.01137903
A11: 1007 | B11: MITROVICË | C11: 64742 | D11: 50171 | E11: 11839 | F11: 11901 | G11: =_xlfn.XLOOKUP(B11,Total!B:B,Total!I:I) -> 954 | H11: =_xlfn.XLOOKUP(B11,Total!B:B,Total!BA:BA) -> 417 | I11: =G11/D11 -> 0.019014969 | J11: =H11/D11 -> 0.0083115744 | K11: =H11-G11 -> -537 | L11: =(H11-G11)/G11 -> -0.56289308 | M11: =G11/E11 -> 0.08058113 | N11: =H11/F11 -> 0.035039072
A12: 100105 | B12: OBILIQ | C12: 22815 | D12: 17367 | E12: 3945 | F12: 4126 | G12: =_xlfn.XLOOKUP(B12,Total!B:B,Total!I:I) -> 254 | H12: =_xlfn.XLOOKUP(B12,Total!B:B,Total!BA:BA) -> 74 | I12: =G12/D12 -> 0.014625439 | J12: =H12/D12 -> 0.0042609547 | K12: =H12-G12 -> -180 | L12: =(H12-G12)/G12 -> -0.70866142 | M12: =G12/E12 -> 0.064385298 | N12: =H12/F12 -> 0.017935046
A13: 1006 | B13: PEJË | C13: 82745 | D13: 65980 | E13: 14551 | F13: 15027 | G13: =_xlfn.XLOOKUP(B13,Total!B:B,Total!I:I) -> 1100 | H13: =_xlfn.XLOOKUP(B13,Total!B:B,Total!BA:BA) -> 524 | I13: =G13/D13 -> 0.016671719 | J13: =H13/D13 -> 0.0079418005 | K13: =H13-G13 -> -576 | L13: =(H13-G13)/G13 -> -0.52363636 | M13: =G13/E13 -> 0.075596179 | N13: =H13/F13 -> 0.034870566
A14: 1009 | B14: PODUJEVË | C14: 70975 | D14: 54812 | E14: 10092 | F14: 10670 | G14: =_xlfn.XLOOKUP(B14,Total!B:B,Total!I:I) -> 485 | H14: =_xlfn.XLOOKUP(B14,Total!B:B,Total!BA:BA) -> 377 | I14: =G14/D14 -> 0.0088484274 | J14: =H14/D14 -> 0.0068780559 | K14: =H14-G14 -> -108 | L14: =(H14-G14)/G14 -> -0.22268041 | M14: =G14/E14 -> 0.048057868 | N14: =H14/F14 -> 0.035332709
... A25: 1005 | B25: PRIZREN | C25: 147246 | D25: 115421 | E25: 15388 | F25: 16152 | G25: =_xlfn.XLOOKUP(B25,Total!B:B,Total!I:I) -> 1273 | H25: =_xlfn.XLOOKUP(B25,Total!B:B,Total!BA:BA) -> 811 | I25: =G25/D25 -> 0.011029189 | J25: =H25/D25 -> 0.007026451 | K25: =H25-G25 -> -462 | L25: =(H25-G25)/G25 -> -0.36292223 | M25: =G25/E25 -> 0.0827268 | N25: =H25/F25 -> 0.0502105
A26: 1004 | B26: GJAKOVË | C26: 78699 | D26: 62970 | E26: 8802 | F26: 8812 | G26: =_xlfn.XLOOKUP(B26,Total!B:B,Total!I:I) -> 1085 | H26: =_xlfn.XLOOKUP(B26,Total!B:B,Total!BA:BA) -> 886 | I26: =G26/D26 -> 0.017230427 | J26: =H26/D26 -> 0.014070192 | K26: =H26-G26 -> -199 | M26: =G26/E26 -> 0.12326744 | N26: =H26/F26 -> 0.10054471
A27: 100702 | B27: VUSHTRRI | C27: 61528 | D27: 47591 | E27: 6269 | F27: 6504 | G27: =_xlfn.XLOOKUP(B27,Total!B:B,Total!I:I) -> 348 | H27: =_xlfn.XLOOKUP(B27,Total!B:B,Total!BA:BA) -> 118 | I27: =G27/D27 -> 0.0073123069 | J27: =H27/D27 -> 0.0024794604 | K27: =H27-G27 -> -230 | L27: =(H27-G27)/G27 -> -0.66091954 | M27: =G27/E27 -> 0.055511246 | N27: =H27/F27 -> 0.018142681
A28: 100503 | B28: MALISHEVË | C28: 43888 | D28: 32516 | E28: 4147 | F28: 4413 | G28: =_xlfn.XLOOKUP(B28,Total!B:B,Total!I:I) -> 157 | H28: =_xlfn.XLOOKUP(B28,Total!B:B,Total!BA:BA) -> 95 | I28: =G28/D28 -> 0.0048283922 | J28: =H28/D28 -> 0.0029216386 | K28: =H28-G28 -> -62 | M28: =G28/E28 -> 0.037858693 | N28: =H28/F28 -> 0.021527306
A29: 100104 | B29: FUSHË KOSOVË | C29: 63949 | D29: 47439 | E29: 6061 | F29: 6301 | G29: =_xlfn.XLOOKUP(B29,Total!B:B,Total!I:I) -> 321 | H29: =_xlfn.XLOOKUP(B29,Total!B:B,Total!BA:BA) -> 134 | I29: =G29/D29 -> 0.0067665845 | J29: =H29/D29 -> 0.0028246801 | K29: =H29-G29 -> -187 | M29: =G29/E29 -> 0.052961557 | N29: =H29/F29 -> 0.021266466
A30: 100706 | B30: ZUBIN POTOK | C30: 3385 | D30: 2940 | E30: 39 | F30: 184 | G30: =_xlfn.XLOOKUP(B30,Total!B:B,Total!I:I) -> 2 | H30: =_xlfn.XLOOKUP(B30,Total!B:B,Total!BA:BA) -> 0 | I30: =G30/D30 -> 0.00068027211 | J30: =H30/D30 -> 0 | K30: =H30-G30 -> -2 | M30: =G30/E30 -> 0.051282051 | N30: =H30/F30 -> 0
A31: 100705 | B31: LEPOSAVIQ | C31: 9485 | D31: 8435 | E31: 193 | F31: 389 | G31: =_xlfn.XLOOKUP(B31,Total!B:B,Total!I:I) -> 24 | H31: =_xlfn.XLOOKUP(B31,Total!B:B,Total!BA:BA) -> 3 | I31: =G31/D31 -> 0.0028452875 | J31: =H31/D31 -> 0.00035566094 | K31: =H31-G31 -> -21 | L31: =(H31-G31)/G31 -> -0.875 | M31: =G31/E31 -> 0.12435233 | N31: =H31/F31 -> 0.0077120823
A32: Ska degë | B32: SHTIME | C32: 24308 | D32: 18586 | E32: 0 | F32: 0 | G32: =_xlfn.XLOOKUP(B32,Total!B:B,Total!I:I) -> 0 | H32: =_xlfn.XLOOKUP(B32,Total!B:B,Total!BA:BA) -> 0 | I32: =G32/D32 -> 0 | J32: =H32/D32 -> 0 | K32: =H32-G32 -> 0
A33: Ska degë | B33: DRAGASH | C33: 28896 | D33: 23559 | E33: 0 | F33: 0 | G33: =_xlfn.XLOOKUP(B33,Total!B:B,Total!I:I) -> 0 | H33: =_xlfn.XLOOKUP(B33,Total!B:B,Total!BA:BA) -> 0 | I33: =G33/D33 -> 0 | J33: =H33/D33 -> 0 | K33: =H33-G33 -> 0
A34: Ska degë | B34: MAMUSHË | C34: 5607 | D34: 4206 | E34: 0 | F34: 0 | G34: =_xlfn.XLOOKUP(B34,Total!B:B,Total!I:I) -> 0 | H34: =_xlfn.XLOOKUP(B34,Total!B:B,Total!BA:BA) -> 0 | I34: =G34/D34 -> 0 | J34: =H34/D34 -> 0 | K34: =H34-G34 -> 0
A35: Ska degë | B35: KLLOKOT | C35: 3041 | D35: 2409 | E35: 0 | F35: 0 | G35: =_xlfn.XLOOKUP(B35,Total!B:B,Total!I:I) -> 0 | H35: =_xlfn.XLOOKUP(B35,Total!B:B,Total!BA:BA) -> 0 | I35: =G35/D35 -> 0 | J35: =H35/D35 -> 0 | K35: =H35-G35 -> 0
A36: Ska degë | B36: NOVOBËRDË | C36: 4493 | D36: 3426 | E36: 0 | F36: 0 | G36: =_xlfn.XLOOKUP(B36,Total!B:B,Total!I:I) -> 0 | H36: =_xlfn.XLOOKUP(B36,Total!B:B,Total!BA:BA) -> 0 | I36: =G36/D36 -> 0 | J36: =H36/D36 -> 0 | K36: =H36-G36 -> 0
A37: Ska degë | B37: JUNIK | C37: 3943 | D37: 3266 | E37: 0 | F37: 0 | G37: =_xlfn.XLOOKUP(B37,Total!B:B,Total!I:I) -> 0 | H37: =_xlfn.XLOOKUP(B37,Total!B:B,Total!BA:BA) -> 0 | I37: =G37/D37 -> 0 | J37: =H37/D37 -> 0 | K37: =H37-G37 -> 0
A38: Ska degë | B38: PARTESH | C38: 3240 | D38: 2762 | E38: 0 | F38: 0 | G38: =_xlfn.XLOOKUP(B38,Total!B:B,Total!I:I) -> 0 | H38: =_xlfn.XLOOKUP(B38,Total!B:B,Total!BA:BA) -> 0 | I38: =G38/D38 -> 0 | J38: =H38/D38 -> 0 | K38: =H38-G38 -> 0
A39: Ska degë | B39: ZVEÇAN | C39: 2867 | D39: 2490 | E39: 0 | F39: 0 | G39: =_xlfn.XLOOKUP(B39,Total!B:B,Total!I:I) -> 0 | H39: =_xlfn.XLOOKUP(B39,Total!B:B,Total!BA:BA) -> 0 | I39: =G39/D39 -> 0 | J39: =H39/D39 -> 0 | K39: =H39-G39 -> 0
A40: Ska degë | B40: RANILLUG | C40: 2481 | D40: 2078 | E40: 0 | F40: 0 | G40: =_xlfn.XLOOKUP(B40,Total!B:B,Total!I:I) -> 0 | H40: =_xlfn.XLOOKUP(B40,Total!B:B,Total!BA:BA) -> 0 | I40: =G40/D40 -> 0 | J40: =H40/D40 -> 0 | K40: =H40-G40 -> 0
B41: Total | C41: =SUM(C3:C40) -> 1602515 | D41: =SUM(D3:D40) -> 1252619 | E41: =SUM(E3:E40) -> 231116 | F41: =SUM(F3:F40) -> 240157 | G41: =SUM(G3:G40) -> 15274 | H41: =SUM(H3:H40) -> 8647 | I41: =G41/D41 -> 0.012193652 | J41: =H41/D41 -> 0.0069031365 | K41: =SUM(K1:K40) -> -6627 | L41: =(H41-G41)/G41 -> -0.43387456 | M41: =G41/E41 -> 0.066088025 | N41: =H41/F41 -> 0.036005613

Sheet SA PI 
G1: 2025 | H1: 2026 | I1: Diff
A2: Branch | B2: Branch/City | C2: Popullsia | D2: Pop >15 | E2: Active Clients 2025 | F2: Active Clients 2026 | G2: SA | H2: SA | I2: 2025 SA vs Population | J2: 2025 SA vs Population | K2: 2025 vs 2026 NO | L2: 2025 vs 2026 | M2: SA per Active Clients 2025 | N2: SA per Active Clients 2026
A3: 100703 | B3: MITROVICË VERIORE | C3: 7920 | D3: 6833 | E3: 9307 | F3: 9261 | G3: =_xlfn.XLOOKUP(B3,Total!B:B,Total!H:H) -> 133 | H3: =_xlfn.XLOOKUP(B3,Total!B:B,Total!AZ:AZ) -> 814 | I3: =G3/D3 -> 0.019464364 | J3: =H3/D3 -> 0.11912776 | K3: =H3-G3 -> 681 | L3: =(H3-G3)/G3 -> 5.1203008 | M3: =G3/E3 -> 0.014290319 | N3: =H3/F3 -> 0.087895476
A4: 100301 | B4: HANI I ELEZIT | C4: 8533 | D4: 6447 | E4: 3155 | F4: 3424 | G4: =_xlfn.XLOOKUP(B4,Total!B:B,Total!H:H) -> 123 | H4: =_xlfn.XLOOKUP(B4,Total!B:B,Total!AZ:AZ) -> 326 | I4: =G4/D4 -> 0.019078641 | J4: =H4/D4 -> 0.050566155 | K4: =H4-G4 -> 203 | L4: =(H4-G4)/G4 -> 1.6504065 | M4: =G4/E4 -> 0.038985737 | N4: =H4/F4 -> 0.09521028
A5: 100303 | B5: SHTËRPCË | C5: 10771 | D5: 9026 | E5: 2881 | F5: 2976 | G5: =_xlfn.XLOOKUP(B5,Total!B:B,Total!H:H) -> 25 | H5: =_xlfn.XLOOKUP(B5,Total!B:B,Total!AZ:AZ) -> 70 | I5: =G5/D5 -> 0.0027697762 | J5: =H5/D5 -> 0.0077553734 | K5: =H5-G5 -> 45 | L5: =(H5-G5)/G5 -> 1.8 | M5: =G5/E5 -> 0.0086775425 | N5: =H5/F5 -> 0.023521505
A6: 100604 | B6: DEÇAN | C6: 27775 | D6: 22138 | E6: 7374 | F6: 7529 | G6: =_xlfn.XLOOKUP(B6,Total!B:B,Total!H:H) -> 454 | H6: =_xlfn.XLOOKUP(B6,Total!B:B,Total!AZ:AZ) -> 728 | I6: =G6/D6 -> 0.020507724 | J6: =H6/D6 -> 0.032884633 | K6: =H6-G6 -> 274 | L6: =(H6-G6)/G6 -> 0.60352423 | M6: =G6/E6 -> 0.06156767 | N6: =H6/F6 -> 0.096692788
A7: 0001 | B7: PRISHTINË | C7: 227466 | D7: 177302 | E7: 45420 | F7: 47635 | G7: =_xlfn.XLOOKUP(B7,Total!B:B,Total!H:H) -> 4854 | H7: =_xlfn.XLOOKUP(B7,Total!B:B,Total!AZ:AZ) -> 9546 | I7: =G7/D7 -> 0.027377018 | J7: =H7/D7 -> 0.05384034 | K7: =H7-G7 -> 4692 | L7: =(H7-G7)/G7 -> 0.96662546 | M7: =G7/E7 -> 0.10686922 | N7: =H7/F7 -> 0.20039887
A8: 100302 | B8: KAÇANIK | C8: 27716 | D8: 21269 | E8: 5730 | F8: 5947 | G8: =_xlfn.XLOOKUP(B8,Total!B:B,Total!H:H) -> 296 | H8: =_xlfn.XLOOKUP(B8,Total!B:B,Total!AZ:AZ) -> 664 | I8: =G8/D8 -> 0.013916968 | J8: =H8/D8 -> 0.031219145 | K8: =H8-G8 -> 368 | L8: =(H8-G8)/G8 -> 1.2432432 | M8: =G8/E8 -> 0.051657941 | N8: =H8/F8 -> 0.11165293
A9: 000103 | B9: GLLOGOC | C9: 48079 | D9: 36276 | E9: 8493 | F9: 8808 | G9: =_xlfn.XLOOKUP(B9,Total!B:B,Total!H:H) -> 366 | H9: =_xlfn.XLOOKUP(B9,Total!B:B,Total!AZ:AZ) -> 937 | I9: =G9/D9 -> 0.010089315 | J9: =H9/D9 -> 0.02582975 | K9: =H9-G9 -> 571 | L9: =(H9-G9)/G9 -> 1.5601093 | M9: =G9/E9 -> 0.043094313 | N9: =H9/F9 -> 0.10638056
A10: 100108 | B10: GRAÇANICË | C10: 18486 | D10: 14806 | E10: 3610 | F10: 3691 | G10: =_xlfn.XLOOKUP(B10,Total!B:B,Total!H:H) -> 30 | H10: =_xlfn.XLOOKUP(B10,Total!B:B,Total!AZ:AZ) -> 151 | I10: =G10/D10 -> 0.0020262056 | J10: =H10/D10 -> 0.010198568 | K10: =H10-G10 -> 121 | L10: =(H10-G10)/G10 -> 4.0333333 | M10: =G10/E10 -> 0.0083102493 | N10: =H10/F10 -> 0.040910322
A11: 1007 | B11: MITROVICË | C11: 64742 | D11: 50171 | E11: 11839 | F11: 11901 | G11: =_xlfn.XLOOKUP(B11,Total!B:B,Total!H:H) -> 679 | H11: =_xlfn.XLOOKUP(B11,Total!B:B,Total!AZ:AZ) -> 1897 | I11: =G11/D11 -> 0.013533715 | J11: =H11/D11 -> 0.037810687 | K11: =H11-G11 -> 1218 | L11: =(H11-G11)/G11 -> 1.7938144 | M11: =G11/E11 -> 0.057352817 | N11: =H11/F11 -> 0.15939837
A12: 100105 | B12: OBILIQ | C12: 22815 | D12: 17367 | E12: 3945 | F12: 4126 | G12: =_xlfn.XLOOKUP(B12,Total!B:B,Total!H:H) -> 139 | H12: =_xlfn.XLOOKUP(B12,Total!B:B,Total!AZ:AZ) -> 482 | I12: =G12/D12 -> 0.0080036851 | J12: =H12/D12 -> 0.027753786 | K12: =H12-G12 -> 343 | L12: =(H12-G12)/G12 -> 2.4676259 | M12: =G12/E12 -> 0.035234474 | N12: =H12/F12 -> 0.11682016
A13: 1006 | B13: PEJË | C13: 82745 | D13: 65980 | E13: 14551 | F13: 15027 | G13: =_xlfn.XLOOKUP(B13,Total!B:B,Total!H:H) -> 1067 | H13: =_xlfn.XLOOKUP(B13,Total!B:B,Total!AZ:AZ) -> 2512 | I13: =G13/D13 -> 0.016171567 | J13: =H13/D13 -> 0.038072143 | K13: =H13-G13 -> 1445 | L13: =(H13-G13)/G13 -> 1.3542643 | M13: =G13/E13 -> 0.073328294 | N13: =H13/F13 -> 0.16716577
A14: 1009 | B14: PODUJEVË | C14: 70975 | D14: 54812 | E14: 10092 | F14: 10670 | G14: =_xlfn.XLOOKUP(B14,Total!B:B,Total!H:H) -> 560 | H14: =_xlfn.XLOOKUP(B14,Total!B:B,Total!AZ:AZ) -> 1089 | I14: =G14/D14 -> 0.010216741 | J14: =H14/D14 -> 0.019867912 | K14: =H14-G14 -> 529 | L14: =(H14-G14)/G14 -> 0.94464286 | M14: =G14/E14 -> 0.055489497 | N14: =H14/F14 -> 0.10206186
... A25: 1005 | B25: PRIZREN | C25: 147246 | D25: 115421 | E25: 15388 | F25: 16152 | G25: =_xlfn.XLOOKUP(B25,Total!B:B,Total!H:H) -> 640 | H25: =_xlfn.XLOOKUP(B25,Total!B:B,Total!AZ:AZ) -> 1743 | I25: =G25/D25 -> 0.0055449182 | J25: =H25/D25 -> 0.015101238 | K25: =H25-G25 -> 1103 | L25: =(H25-G25)/G25 -> 1.7234375 | M25: =G25/E25 -> 0.04159085 | N25: =H25/F25 -> 0.10791233
A26: 1004 | B26: GJAKOVË | C26: 78699 | D26: 62970 | E26: 8802 | F26: 8812 | G26: =_xlfn.XLOOKUP(B26,Total!B:B,Total!H:H) -> 568 | H26: =_xlfn.XLOOKUP(B26,Total!B:B,Total!AZ:AZ) -> 1178 | I26: =G26/D26 -> 0.0090201683 | J26: =H26/D26 -> 0.018707321 | K26: =H26-G26 -> 610 | M26: =G26/E26 -> 0.064530788 | N26: =H26/F26 -> 0.13368134
A27: 100702 | B27: VUSHTRRI | C27: 61528 | D27: 47591 | E27: 6269 | F27: 6504 | G27: =_xlfn.XLOOKUP(B27,Total!B:B,Total!H:H) -> 323 | H27: =_xlfn.XLOOKUP(B27,Total!B:B,Total!AZ:AZ) -> 828 | I27: =G27/D27 -> 0.0067869975 | J27: =H27/D27 -> 0.017398248 | K27: =H27-G27 -> 505 | L27: =(H27-G27)/G27 -> 1.5634675 | M27: =G27/E27 -> 0.051523369 | N27: =H27/F27 -> 0.12730627
A28: 100503 | B28: MALISHEVË | C28: 43888 | D28: 32516 | E28: 4147 | F28: 4413 | G28: =_xlfn.XLOOKUP(B28,Total!B:B,Total!H:H) -> 201 | H28: =_xlfn.XLOOKUP(B28,Total!B:B,Total!AZ:AZ) -> 448 | I28: =G28/D28 -> 0.0061815721 | J28: =H28/D28 -> 0.013777832 | K28: =H28-G28 -> 247 | M28: =G28/E28 -> 0.048468773 | N28: =H28/F28 -> 0.10151824
A29: 100104 | B29: FUSHË KOSOVË | C29: 63949 | D29: 47439 | E29: 6061 | F29: 6301 | G29: =_xlfn.XLOOKUP(B29,Total!B:B,Total!H:H) -> 367 | H29: =_xlfn.XLOOKUP(B29,Total!B:B,Total!AZ:AZ) -> 782 | I29: =G29/D29 -> 0.0077362508 | J29: =H29/D29 -> 0.016484327 | K29: =H29-G29 -> 415 | M29: =G29/E29 -> 0.060551064 | N29: =H29/F29 -> 0.12410728
A30: 100706 | B30: ZUBIN POTOK | C30: 3385 | D30: 2940 | E30: 39 | F30: 184 | G30: =_xlfn.XLOOKUP(B30,Total!B:B,Total!H:H) -> 0 | H30: =_xlfn.XLOOKUP(B30,Total!B:B,Total!AZ:AZ) -> 5 | I30: =G30/D30 -> 0 | J30: =H30/D30 -> 0.0017006803 | K30: =H30-G30 -> 5 | M30: =G30/E30 -> 0 | N30: =H30/F30 -> 0.027173913
A31: 100705 | B31: LEPOSAVIQ | C31: 9485 | D31: 8435 | E31: 193 | F31: 389 | G31: 1e-06 | H31: =_xlfn.XLOOKUP(B31,Total!B:B,Total!AZ:AZ) -> 52 | I31: =G31/D31 -> 1.1855365e-10 | J31: =H31/D31 -> 0.0061647896 | K31: =H31-G31 -> 51.999999 | M31: =G31/E31 -> 5.1813472e-09 | N31: =H31/F31 -> 0.13367609
A32: Ska degë | B32: SHTIME | C32: 24308 | D32: 18586 | E32: 0 | F32: 0 | G32: =_xlfn.XLOOKUP(B32,Total!B:B,Total!H:H) -> 0 | H32: =_xlfn.XLOOKUP(B32,Total!B:B,Total!AZ:AZ) -> 0 | I32: =G32/D32 -> 0 | J32: =H32/D32 -> 0 | K32: =H32-G32 -> 0
A33: Ska degë | B33: DRAGASH | C33: 28896 | D33: 23559 | E33: 0 | F33: 0 | G33: =_xlfn.XLOOKUP(B33,Total!B:B,Total!H:H) -> 0 | H33: =_xlfn.XLOOKUP(B33,Total!B:B,Total!AZ:AZ) -> 0 | I33: =G33/D33 -> 0 | J33: =H33/D33 -> 0 | K33: =H33-G33 -> 0
A34: Ska degë | B34: MAMUSHË | C34: 5607 | D34: 4206 | E34: 0 | F34: 0 | G34: =_xlfn.XLOOKUP(B34,Total!B:B,Total!H:H) -> 0 | H34: =_xlfn.XLOOKUP(B34,Total!B:B,Total!AZ:AZ) -> 0 | I34: =G34/D34 -> 0 | J34: =H34/D34 -> 0 | K34: =H34-G34 -> 0
A35: Ska degë | B35: KLLOKOT | C35: 3041 | D35: 2409 | E35: 0 | F35: 0 | G35: =_xlfn.XLOOKUP(B35,Total!B:B,Total!H:H) -> 0 | H35: =_xlfn.XLOOKUP(B35,Total!B:B,Total!AZ:AZ) -> 0 | I35: =G35/D35 -> 0 | J35: =H35/D35 -> 0 | K35: =H35-G35 -> 0
A36: Ska degë | B36: NOVOBËRDË | C36: 4493 | D36: 3426 | E36: 0 | F36: 0 | G36: =_xlfn.XLOOKUP(B36,Total!B:B,Total!H:H) -> 0 | H36: =_xlfn.XLOOKUP(B36,Total!B:B,Total!AZ:AZ) -> 0 | I36: =G36/D36 -> 0 | J36: =H36/D36 -> 0 | K36: =H36-G36 -> 0
A37: Ska degë | B37: JUNIK | C37: 3943 | D37: 3266 | E37: 0 | F37: 0 | G37: =_xlfn.XLOOKUP(B37,Total!B:B,Total!H:H) -> 0 | H37: =_xlfn.XLOOKUP(B37,Total!B:B,Total!AZ:AZ) -> 0 | I37: =G37/D37 -> 0 | J37: =H37/D37 -> 0 | K37: =H37-G37 -> 0
A38: Ska degë | B38: PARTESH | C38: 3240 | D38: 2762 | E38: 0 | F38: 0 | G38: =_xlfn.XLOOKUP(B38,Total!B:B,Total!H:H) -> 0 | H38: =_xlfn.XLOOKUP(B38,Total!B:B,Total!AZ:AZ) -> 0 | I38: =G38/D38 -> 0 | J38: =H38/D38 -> 0 | K38: =H38-G38 -> 0
A39: Ska degë | B39: ZVEÇAN | C39: 2867 | D39: 2490 | E39: 0 | F39: 0 | G39: =_xlfn.XLOOKUP(B39,Total!B:B,Total!H:H) -> 0 | H39: =_xlfn.XLOOKUP(B39,Total!B:B,Total!AZ:AZ) -> 0 | I39: =G39/D39 -> 0 | J39: =H39/D39 -> 0 | K39: =H39-G39 -> 0
A40: Ska degë | B40: RANILLUG | C40: 2481 | D40: 2078 | E40: 0 | F40: 0 | G40: =_xlfn.XLOOKUP(B40,Total!B:B,Total!H:H) -> 0 | H40: =_xlfn.XLOOKUP(B40,Total!B:B,Total!AZ:AZ) -> 0 | I40: =G40/D40 -> 0 | J40: =H40/D40 -> 0 | K40: =H40-G40 -> 0
B41: Total | C41: =SUM(C3:C40) -> 1602515 | D41: =SUM(D3:D40) -> 1252619 | E41: =SUM(E3:E40) -> 231116 | F41: =SUM(F3:F40) -> 240157 | G41: =SUM(G3:G40) -> 13791 | H41: =SUM(H3:H40) -> 30615 | I41: =G41/D41 -> 0.011009732 | J41: =H41/D41 -> 0.024440792 | K41: =SUM(K1:K40) -> 16824 | L41: =(H41-G41)/G41 -> 1.219926 | M41: =G41/E41 -> 0.059671334 | N41: =H41/F41 -> 0.12747911

Sheet Mortgage Loans
G1: 2025 | H1: 2026 | I1: Diff
A2: Branch | B2: Branch/City | C2: Popullsia | D2: Pop >15 | E2: Active Clients 2025 | F2: Active Clients 2026 | G2: Mortgage Loans | H2: Mortgage Loans | I2: 2025 Loan vs Population | J2: 2025 Loan vs Population | K2: # 2025 vs 2026 | L2: % 2025 vs 2026 | M2: Loan per Active Clients 2025 | N2: Loan per Active Clients 2026
A3: 100703 | B3: MITROVICË VERIORE | C3: 7920 | D3: 6833 | E3: 9307 | F3: 9261 | G3: =_xlfn.XLOOKUP(B3,Total!B:B,Total!J:J) -> 104 | H3: =_xlfn.XLOOKUP(B3,Total!B:B,Total!BB:BB) -> 89 | I3: =G3/D3 -> 0.015220255 | J3: =H3/D3 -> 0.013025026 | K3: =H3-G3 -> -15 | L3: =K3/G3 -> -0.14423077 | M3: =G3/E3 -> 0.011174385 | N3: =H3/F3 -> 0.0096101933
A4: 100301 | B4: HANI I ELEZIT | C4: 8533 | D4: 6447 | E4: 3155 | F4: 3424 | G4: =_xlfn.XLOOKUP(B4,Total!B:B,Total!J:J) -> 91 | H4: =_xlfn.XLOOKUP(B4,Total!B:B,Total!BB:BB) -> 93 | I4: =G4/D4 -> 0.014115092 | J4: =H4/D4 -> 0.014425314 | K4: =H4-G4 -> 2 | L4: =(H4-G4)/G4 -> 0.021978022 | M4: =G4/E4 -> 0.028843106 | N4: =H4/F4 -> 0.027161215
A5: 100303 | B5: SHTËRPCË | C5: 10771 | D5: 9026 | E5: 2881 | F5: 2976 | G5: =_xlfn.XLOOKUP(B5,Total!B:B,Total!J:J) -> 68 | H5: =_xlfn.XLOOKUP(B5,Total!B:B,Total!BB:BB) -> 71 | I5: =G5/D5 -> 0.0075337913 | J5: =H5/D5 -> 0.0078661644 | K5: =H5-G5 -> 3 | L5: =(H5-G5)/G5 -> 0.044117647 | M5: =G5/E5 -> 0.023602916 | N5: =H5/F5 -> 0.023857527
A6: 100604 | B6: DEÇAN | C6: 27775 | D6: 22138 | E6: 7374 | F6: 7529 | G6: =_xlfn.XLOOKUP(B6,Total!B:B,Total!J:J) -> 119 | H6: =_xlfn.XLOOKUP(B6,Total!B:B,Total!BB:BB) -> 123 | I6: =G6/D6 -> 0.0053753727 | J6: =H6/D6 -> 0.0055560575 | K6: =H6-G6 -> 4 | L6: =(H6-G6)/G6 -> 0.033613445 | M6: =G6/E6 -> 0.016137781 | N6: =H6/F6 -> 0.016336831
A7: 0001 | B7: PRISHTINË | C7: 227466 | D7: 177302 | E7: 45420 | F7: 47635 | G7: =_xlfn.XLOOKUP(B7,Total!B:B,Total!J:J) -> 3305 | H7: =_xlfn.XLOOKUP(B7,Total!B:B,Total!BB:BB) -> 3386 | I7: =G7/D7 -> 0.018640512 | J7: =H7/D7 -> 0.019097359 | K7: =H7-G7 -> 81 | L7: =(H7-G7)/G7 -> 0.024508321 | M7: =G7/E7 -> 0.072765302 | N7: =H7/F7 -> 0.071082187
A8: 100302 | B8: KAÇANIK | C8: 27716 | D8: 21269 | E8: 5730 | F8: 5947 | G8: =_xlfn.XLOOKUP(B8,Total!B:B,Total!J:J) -> 148 | H8: =_xlfn.XLOOKUP(B8,Total!B:B,Total!BB:BB) -> 145 | I8: =G8/D8 -> 0.0069584842 | J8: =H8/D8 -> 0.0068174338 | K8: =H8-G8 -> -3 | L8: =(H8-G8)/G8 -> -0.02027027 | M8: =G8/E8 -> 0.02582897 | N8: =H8/F8 -> 0.024382041
A9: 000103 | B9: GLLOGOC | C9: 48079 | D9: 36276 | E9: 8493 | F9: 8808 | G9: =_xlfn.XLOOKUP(B9,Total!B:B,Total!J:J) -> 350 | H9: =_xlfn.XLOOKUP(B9,Total!B:B,Total!BB:BB) -> 331 | I9: =G9/D9 -> 0.0096482523 | J9: =H9/D9 -> 0.00912449 | K9: =H9-G9 -> -19 | L9: =(H9-G9)/G9 -> -0.054285714 | M9: =G9/E9 -> 0.041210409 | N9: =H9/F9 -> 0.037579473
A10: 100108 | B10: GRAÇANICË | C10: 18486 | D10: 14806 | E10: 3610 | F10: 3691 | G10: =_xlfn.XLOOKUP(B10,Total!B:B,Total!J:J) -> 17 | H10: =_xlfn.XLOOKUP(B10,Total!B:B,Total!BB:BB) -> 15 | I10: =G10/D10 -> 0.0011481832 | J10: =H10/D10 -> 0.0010131028 | K10: =H10-G10 -> -2 | L10: =(H10-G10)/G10 -> -0.11764706 | M10: =G10/E10 -> 0.0047091413 | N10: =H10/F10 -> 0.0040639393
A11: 1007 | B11: MITROVICË | C11: 64742 | D11: 50171 | E11: 11839 | F11: 11901 | G11: =_xlfn.XLOOKUP(B11,Total!B:B,Total!J:J) -> 452 | H11: =_xlfn.XLOOKUP(B11,Total!B:B,Total!BB:BB) -> 482 | I11: =G11/D11 -> 0.0090091886 | J11: =H11/D11 -> 0.0096071436 | K11: =H11-G11 -> 30 | L11: =(H11-G11)/G11 -> 0.066371681 | M11: =G11/E11 -> 0.0381789 | N11: =H11/F11 -> 0.040500798
A12: 100105 | B12: OBILIQ | C12: 22815 | D12: 17367 | E12: 3945 | F12: 4126 | G12: =_xlfn.XLOOKUP(B12,Total!B:B,Total!J:J) -> 90 | H12: =_xlfn.XLOOKUP(B12,Total!B:B,Total!BB:BB) -> 94 | I12: =G12/D12 -> 0.0051822422 | J12: =H12/D12 -> 0.0054125641 | K12: =H12-G12 -> 4 | L12: =(H12-G12)/G12 -> 0.044444444 | M12: =G12/E12 -> 0.022813688 | N12: =H12/F12 -> 0.022782356
A13: 1006 | B13: PEJË | C13: 82745 | D13: 65980 | E13: 14551 | F13: 15027 | G13: =_xlfn.XLOOKUP(B13,Total!B:B,Total!J:J) -> 441 | H13: =_xlfn.XLOOKUP(B13,Total!B:B,Total!BB:BB) -> 434 | I13: =G13/D13 -> 0.0066838436 | J13: =H13/D13 -> 0.0065777508 | K13: =H13-G13 -> -7 | L13: =(H13-G13)/G13 -> -0.015873016 | M13: =G13/E13 -> 0.030307195 | N13: =H13/F13 -> 0.028881347
A14: 1009 | B14: PODUJEVË | C14: 70975 | D14: 54812 | E14: 10092 | F14: 10670 | G14: =_xlfn.XLOOKUP(B14,Total!B:B,Total!J:J) -> 252 | H14: =_xlfn.XLOOKUP(B14,Total!B:B,Total!BB:BB) -> 243 | I14: =G14/D14 -> 0.0045975334 | J14: =H14/D14 -> 0.0044333358 | K14: =H14-G14 -> -9 | L14: =(H14-G14)/G14 -> -0.035714286 | M14: =G14/E14 -> 0.024970273 | N14: =H14/F14 -> 0.022774133
A15: 100603 | B15: ISTOG | C15: 33008 | D15: 26385 | E15: 4844 | F15: 5105 | G15: =_xlfn.XLOOKUP(B15,Total!B:B,Total!J:J) -> 102 | H15: =_xlfn.XLOOKUP(B15,Total!B:B,Total!BB:BB) -> 105 | I15: =G15/D15 -> 0.0038658329 | J15: =H15/D15 -> 0.0039795338 | K15: =H15-G15 -> 3 | L15: =(H15-G15)/G15 -> 0.029411765 | M15: =G15/E15 -> 0.021056978 | N15: =H15/F15 -> 0.020568071
... A25: 1005 | B25: PRIZREN | C25: 147246 | D25: 115421 | E25: 15388 | F25: 16152 | G25: =_xlfn.XLOOKUP(B25,Total!B:B,Total!J:J) -> 455 | H25: =_xlfn.XLOOKUP(B25,Total!B:B,Total!BB:BB) -> 427 | I25: =G25/D25 -> 0.0039420903 | J25: =H25/D25 -> 0.0036995001 | K25: =H25-G25 -> -28 | L25: =(H25-G25)/G25 -> -0.061538462 | M25: =G25/E25 -> 0.029568495 | N25: =H25/F25 -> 0.026436355
A26: 1004 | B26: GJAKOVË | C26: 78699 | D26: 62970 | E26: 8802 | F26: 8812 | G26: =_xlfn.XLOOKUP(B26,Total!B:B,Total!J:J) -> 503 | H26: =_xlfn.XLOOKUP(B26,Total!B:B,Total!BB:BB) -> 447 | I26: =G26/D26 -> 0.0079879308 | J26: =H26/D26 -> 0.0070986184 | K26: =H26-G26 -> -56 | M26: =G26/E26 -> 0.057146103 | N26: =H26/F26 -> 0.050726282
A27: 100702 | B27: VUSHTRRI | C27: 61528 | D27: 47591 | E27: 6269 | F27: 6504 | G27: =_xlfn.XLOOKUP(B27,Total!B:B,Total!J:J) -> 170 | H27: =_xlfn.XLOOKUP(B27,Total!B:B,Total!BB:BB) -> 180 | I27: =G27/D27 -> 0.003572104 | J27: =H27/D27 -> 0.0037822277 | K27: =H27-G27 -> 10 | L27: =(H27-G27)/G27 -> 0.058823529 | M27: =G27/E27 -> 0.027117563 | N27: =H27/F27 -> 0.027675277
A28: 100503 | B28: MALISHEVË | C28: 43888 | D28: 32516 | E28: 4147 | F28: 4413 | G28: =_xlfn.XLOOKUP(B28,Total!B:B,Total!J:J) -> 156 | H28: =_xlfn.XLOOKUP(B28,Total!B:B,Total!BB:BB) -> 148 | I28: =G28/D28 -> 0.0047976381 | J28: =H28/D28 -> 0.0045516054 | K28: =H28-G28 -> -8 | M28: =G28/E28 -> 0.037617555 | N28: =H28/F28 -> 0.033537276
A29: 100104 | B29: FUSHË KOSOVË | C29: 63949 | D29: 47439 | E29: 6061 | F29: 6301 | G29: =_xlfn.XLOOKUP(B29,Total!B:B,Total!J:J) -> 256 | H29: =_xlfn.XLOOKUP(B29,Total!B:B,Total!BB:BB) -> 287 | I29: =G29/D29 -> 0.0053964038 | J29: =H29/D29 -> 0.0060498746 | K29: =H29-G29 -> 31 | M29: =G29/E29 -> 0.042237255 | N29: =H29/F29 -> 0.045548326
A30: 100706 | B30: ZUBIN POTOK | C30: 3385 | D30: 2940 | E30: 39 | F30: 184 | G30: =_xlfn.XLOOKUP(B30,Total!B:B,Total!J:J) -> 0 | H30: =_xlfn.XLOOKUP(B30,Total!B:B,Total!BB:BB) -> 0 | I30: =G30/D30 -> 0 | J30: =H30/D30 -> 0 | K30: =H30-G30 -> 0 | M30: =G30/E30 -> 0 | N30: =H30/F30 -> 0
A31: 100705 | B31: LEPOSAVIQ | C31: 9485 | D31: 8435 | E31: 193 | F31: 389 | G31: =_xlfn.XLOOKUP(B31,Total!B:B,Total!J:J) -> 0 | H31: =_xlfn.XLOOKUP(B31,Total!B:B,Total!BB:BB) -> 0 | I31: =G31/D31 -> 0 | J31: =H31/D31 -> 0 | K31: =H31-G31 -> 0 | M31: =G31/E31 -> 0 | N31: =H31/F31 -> 0
A32: Ska degë | B32: SHTIME | C32: 24308 | D32: 18586 | E32: 0 | F32: 0 | G32: =_xlfn.XLOOKUP(B32,Total!B:B,Total!J:J) -> 0 | H32: =_xlfn.XLOOKUP(B32,Total!B:B,Total!BB:BB) -> 0 | I32: =G32/D32 -> 0 | J32: =H32/D32 -> 0 | K32: =H32-G32 -> 0
A33: Ska degë | B33: DRAGASH | C33: 28896 | D33: 23559 | E33: 0 | F33: 0 | G33: =_xlfn.XLOOKUP(B33,Total!B:B,Total!J:J) -> 0 | H33: =_xlfn.XLOOKUP(B33,Total!B:B,Total!BB:BB) -> 0 | I33: =G33/D33 -> 0 | J33: =H33/D33 -> 0 | K33: =H33-G33 -> 0
A34: Ska degë | B34: MAMUSHË | C34: 5607 | D34: 4206 | E34: 0 | F34: 0 | G34: =_xlfn.XLOOKUP(B34,Total!B:B,Total!J:J) -> 0 | H34: =_xlfn.XLOOKUP(B34,Total!B:B,Total!BB:BB) -> 0 | I34: =G34/D34 -> 0 | J34: =H34/D34 -> 0 | K34: =H34-G34 -> 0
A35: Ska degë | B35: KLLOKOT | C35: 3041 | D35: 2409 | E35: 0 | F35: 0 | G35: =_xlfn.XLOOKUP(B35,Total!B:B,Total!J:J) -> 0 | H35: =_xlfn.XLOOKUP(B35,Total!B:B,Total!BB:BB) -> 0 | I35: =G35/D35 -> 0 | J35: =H35/D35 -> 0 | K35: =H35-G35 -> 0
A36: Ska degë | B36: NOVOBËRDË | C36: 4493 | D36: 3426 | E36: 0 | F36: 0 | G36: =_xlfn.XLOOKUP(B36,Total!B:B,Total!J:J) -> 0 | H36: =_xlfn.XLOOKUP(B36,Total!B:B,Total!BB:BB) -> 0 | I36: =G36/D36 -> 0 | J36: =H36/D36 -> 0 | K36: =H36-G36 -> 0
A37: Ska degë | B37: JUNIK | C37: 3943 | D37: 3266 | E37: 0 | F37: 0 | G37: =_xlfn.XLOOKUP(B37,Total!B:B,Total!J:J) -> 0 | H37: =_xlfn.XLOOKUP(B37,Total!B:B,Total!BB:BB) -> 0 | I37: =G37/D37 -> 0 | J37: =H37/D37 -> 0 | K37: =H37-G37 -> 0
A38: Ska degë | B38: PARTESH | C38: 3240 | D38: 2762 | E38: 0 | F38: 0 | G38: =_xlfn.XLOOKUP(B38,Total!B:B,Total!J:J) -> 0 | H38: =_xlfn.XLOOKUP(B38,Total!B:B,Total!BB:BB) -> 0 | I38: =G38/D38 -> 0 | J38: =H38/D38 -> 0 | K38: =H38-G38 -> 0
A39: Ska degë | B39: ZVEÇAN | C39: 2867 | D39: 2490 | E39: 0 | F39: 0 | G39: =_xlfn.XLOOKUP(B39,Total!B:B,Total!J:J) -> 0 | H39: =_xlfn.XLOOKUP(B39,Total!B:B,Total!BB:BB) -> 0 | I39: =G39/D39 -> 0 | J39: =H39/D39 -> 0 | K39: =H39-G39 -> 0
A40: Ska degë | B40: RANILLUG | C40: 2481 | D40: 2078 | E40: 0 | F40: 0 | G40: =_xlfn.XLOOKUP(B40,Total!B:B,Total!J:J) -> 0 | H40: =_xlfn.XLOOKUP(B40,Total!B:B,Total!BB:BB) -> 0 | I40: =G40/D40 -> 0 | J40: =H40/D40 -> 0 | K40: =H40-G40 -> 0
B41: Total | C41: =SUM(C3:C40) -> 1602515 | D41: =SUM(D3:D40) -> 1252619 | E41: =SUM(E3:E40) -> 231116 | F41: =SUM(F3:F40) -> 240157 | G41: =SUM(G3:G40) -> 9177 | H41: =SUM(H3:H40) -> 9381 | I41: =G41/D41 -> 0.00732625 | J41: =H41/D41 -> 0.0074891088 | K41: =SUM(K1:K40) -> 204 | L41: =(H41-G41)/G41 -> 0.022229487 | M41: =G41/E41 -> 0.039707333 | N41: =H41/F41 -> 0.039061947

Sheet Consumer Loans
G1: 2025 | H1: 2026 | I1: Diff
A2: Branch | B2: Branch/City | C2: Popullsia | D2: Pop >15 | E2: Active Clients 2025 | F2: Active Clients 2026 | G2: Consumer Loans | H2: Consumer Loans | I2: 2025 Loan vs Population | J2: 2025 Loan vs Population | K2: # 2025 vs 2026 | L2: % 2025 vs 2026 | M2: Loan per Active Clients 2025 | N2: Loan per Active Clients 2026
A3: 100703 | B3: MITROVICË VERIORE | C3: 7920 | D3: 6833 | E3: 9307 | F3: 9261 | G3: =_xlfn.XLOOKUP(B3,Total!B:B,Total!K:K) -> 496 | H3: =_xlfn.XLOOKUP(B3,Total!B:B,Total!BC:BC) -> 403 | I3: =G3/D3 -> 0.072588907 | J3: =H3/D3 -> 0.058978487 | K3: =H3-G3 -> -93 | L3: =K3/G3 -> -0.1875 | M3: =G3/E3 -> 0.05329322 | N3: =H3/F3 -> 0.043515819
A4: 100301 | B4: HANI I ELEZIT | C4: 8533 | D4: 6447 | E4: 3155 | F4: 3424 | G4: =_xlfn.XLOOKUP(B4,Total!B:B,Total!K:K) -> 410 | H4: =_xlfn.XLOOKUP(B4,Total!B:B,Total!BC:BC) -> 522 | I4: =G4/D4 -> 0.063595471 | J4: =H4/D4 -> 0.080967892 | K4: =H4-G4 -> 112 | L4: =(H4-G4)/G4 -> 0.27317073 | M4: =G4/E4 -> 0.12995246 | N4: =H4/F4 -> 0.15245327
A5: 100303 | B5: SHTËRPCË | C5: 10771 | D5: 9026 | E5: 2881 | F5: 2976 | G5: =_xlfn.XLOOKUP(B5,Total!B:B,Total!K:K) -> 299 | H5: =_xlfn.XLOOKUP(B5,Total!B:B,Total!BC:BC) -> 322 | I5: =G5/D5 -> 0.033126523 | J5: =H5/D5 -> 0.035674717 | K5: =H5-G5 -> 23 | L5: =(H5-G5)/G5 -> 0.076923077 | M5: =G5/E5 -> 0.10378341 | N5: =H5/F5 -> 0.10819892
